Workbook

Sheet רשימת מכשור 2015
A1: הרשימה הזו מייצגת את כל המכשור שהיה מותקן בפרוטליקס בשנת 2015 ושימשה כרשימת הציוד לצורך החלטה על תוכנית רכישה של מלאי ח"ח מכשור. הרשימה אינה עדכנית ולא ניתן להסתמך עליה (עמית 04/02/21)
A2: תיאור הציוד | B2: יצרן | C2: דגם | D2: מערכת | E2: מס' Tag | F2: הערכת מחיר ב₪ | G2: הערה
A3: מד עכירות | B3: מודקון / לאמיקו | C3: OPTEK - CONVERTOR MODEL | D3: צנטרפוגה | E3: QIAH 02-9-042 | F3: 70000
A4: אנלייזר פחמן אורגני | B4: THORNTON | C4: 5000 | D4: PW פיילוט | E4: 1-TOC-1 | F4: 50000
A5: אנלייזר פחמן אורגני | B5: Mettler Toledo | C5: 5000TOC | D5: PW STORAGE 2500 | E5: 1-1-606-TOC-001 | F5: 50000
A6: אנלייזר פחמן אורגני | B6: METTLER TOLEDO | C6: 5000TOC | D6: WFI-PRODUCTION/STORAGE | E6: 1-1-25-TOC-1 | F6: 50000
A7: multi chanel | B7: Mettler Toledo | C7: 770MAX | D7: 5000 | E7: N/A | F7: 10000
A8: multi chanel | B8: Mettler Toledo | C8: 770MAX | D8: 2500 | E8: N/A | F8: 10000
A9: אנלייזר קשיות | B9: ABB ISRAEL | C9: AW101/.1.2.1.1 | D9: HSW | E9: 1-1-57-HIC-1 | F9: 18000
A10: מד זרימה | B10: Liquid Controls Sponsler | C10: SP3/4-CS-PHL-3/4G-6MCIX3A | D10: CDI | E10: 1-1-134-FIC-1 | F10: 14000
A11: מד זרימה | B11: Liquid Controls Sponsler | C11: SP3/4-CS-PHL-3/4G-6MCIX3A | D11: CDI | E11: 1-1-134-FIC-3 | F11: 14000
A12: משדר זרימה | B12: Liquid Controls Sponsler | C12: SP3/4-CS-PHL -3/4G-6MCIX3A | D12: PW PRODUCTION 2500 | E12: 1-1-604-FIT-001 | F12: 12000
A13: מד מפלס | B13: E+H | C13: MICROPILOT M FMR245-AETEJAA2AA | D13: NaOH | E13: 1-1-5-LC-1 | F13: 120000
A14: מד מפלס | B14: E+H | C14: MICROPILOT M FMR245-AETEJAA2AA | D14: ACID | E14: 1-1-141-LC-1 | F14: 120000
A15: מד מפלס | B15: E+H | C15: LEVELFLEX M FMP43-AS5TDJB21A2B | D15: WFI-PRODUCTION/STORAGE | E15: 25-LT-001 | F15: 12000
A16: מד מפלס | B16: E+H | C16: LEVELFLEX M FMP41C-AATDKB21A2A | D16: SW SYSTEM | E16: 1-1-132-LIC-1 | F16: 12000
A17: משדר לחץ | B17: LABOM | C17: LABOM - CV3110 | D17: צנטרפוגה | E17: PIAL 02-9-020 | F17: 10000
A18: משדר לחץ | B18: LABOM | C18: LABOM - CV3110 | D18: צנטרפוגה | E18: PIAL 02-9-534 | F18: 10000
A19: multi chanel | B19: THORNTON | C19: 770 max | D19: PW פיילוט | F19: 10000
A20: מד כלור | B20: E+H | C20: transmitter : liquisys m CCM253-EK8005 FLOWFIT-W CCA250 | D20: CLW | E20: 1-1-1-CLIC-1 | F20: 7000
A21: מד מפלס | B21: E+H | C21: LIQUICAP M FMI52-A1BTDJA2A1A | D21: CLW | E21: 1-1-1-LC-1 | F21: 10000
A22: מד מפלס | B22: E+H | C22: LIQUICAP M FMI52-A1BTDJA2A1A | D22: HSW | E22: 1-1-57-LC-1 | F22: 10000
A23: multi chanel | B23: torenton | C23: torenton | D23: WFI-PRODUCTION/STORAGE | E23: 25-CIT-1 | F23: 10000
A24: משדר לחץ | B24: LABOM | C24: LABOM - CV3110 | D24: צנטרפוגה | E24: PIC 02-9-047 | F24: 10000
A25: מד זרימה | B25: ABB ISRAEL | C25: ABB - FEH311 | D25: צנטרפוגה | E25: FIC 02-9-041 | F25: 9133
A26: משדר חמצן | B26: Drager | C26: polytron 7000 | D26: GAS phase cell bank | E26: 1-2-2010-OM-2 | F26: 7500
A27: מד כלור | B27: E+H | C27: Element : ccs140 transmitter : liquisys m cell : flowfit cca250 | D27: PRETREATMENT SYSTEM | E27: 1-1-131-CLIC-1 | F27: 7000 | G27: ניתן לישם פתרון ידני
A28: אלקטרודת מוליכות | B28: E+H | C28: Element : cls21-c1e4a Transmitter : liquisys m clm253-cd8005 | D28: PRETREATMENT SYSTEM | E28: 1-1-131-CIT 1 | F28: 7000 | G28: פוגע באיכות הסביבה ולכן סומן כמשבית
A29: אלקטרודת מוליכות | B29: Mettler Toledo | C29: Inpro 7108 1.5"TC 5200800 M400 | D29: MEDIA | E29: 1-1-56-CIC-1 | F29: 4000
A30: מד רדוקס | B30: EUTECH INSTRUMENT | C30: Sensor: Pt4805-DPA-SC-S8 Transmiter: ALPHA pH800 | D30: SW SYSTEM | E30: 1-1-132-ORP-1 | F30: 7000
A31: מד לחץ | B31: LABOM | C31: LABOM - BH4200 | D31: צנטרפוגה | E31: PI 02-9-019 | F31: 6708
A32: מד רעידות | B32: GEAיצור עצמי | C32: HW - sensor messtechnik pch | D32: צנטרפוגה | E32: NAH/HH01-9-018 | F32: 6615
A33: משדר לחץ | B33: E+H | C33: PMP46-RE13SBJPGD | D33: PW STORAGE 2500 | E33: 1-1-606-PIT-007 | F33: 6000
A34: משדר לחץ | B34: Carabar M | C34: D800AB0112A | D34: WFI-PRODUCTION/STORAGE | E34: 25-PIC-1 | F34: 6000
A35: משדר לחץ | B35: E+H | C35: CERABAR M PMC45 | D35: RO PRODUCTION | E35: 1-1-133-PIC-2 | F35: 6000
A36: משדר לחץ | B36: E+H | C36: CB012C01024 | D36: RO PRODUCTION | E36: 1-1-133-PIC-6 | F36: 6000
A37: מד ובקר לחץ | B37: E+H | C37: CB012C01024 | D37: RO PRODUCTION | E37: 1-1-133-PIC-1 | F37: 6000
A38: משדר לחץ | B38: E+H | C38: CERABAR M PMP46-RE17P1JPDGD | D38: MEDIA | E38: 1-1-56-PC-1 | F38: 6000
A39: משדר לחץ | B39: E+H | C39: CERABAR M PMP46-RE17P1JPDGD | D39: MEDIA | E39: 1-1-56-PC-2 | F39: 6000
A40: משדר לחץ | B40: E+H | C40: CERABAR M PMP46-RE13SVJPDGD | D40: CRUDE | E40: 1-1-28-PC-2 | F40: 6000
...

Sheet חח מכשור - מידע והחלטה 2015
A2: הרשימה הזו מייצגת את כל המכשור שהיה מותקן בפרוטליקס בשנת 2015 ושימשה כמערכת שיקולים להחלטה על תוכנית רכישה של מלאי ח"ח מכשור. הרשימה אינה עדכנית ולא ניתן להסתמך עליה (עמית 04/02/21)
A3: תיאור הציוד | B3: יצרן | C3: דגם | D3: מערכת | E3: מס' Tag | F3: מחיר ב₪ | G3: כמות נדרשת למלאי | H3: סה"כ | I3: קיים במלאי כן/לא | J3: סיכוי לכשל | K3: משבית/ לא משבית | L3: זמן הספקה [חודש] | M3: תוצאת חישוב | N3: עלות השבתה ליום | O3: האם יש הסכם שירות ? | P3: כמות מאותו דגם | Q3: הערה
A4: מד עכירות | B4: מודקון / לאמיקו | C4: OPTEK - CONVERTOR MODEL | D4: צנטרפוגה | E4: QIAH 02-9-042 | F4: 70000 | G4: 1 | H4: =G4*F4 -> 70000 | J4: 1 | K4: 0 | L4: 2 | M4: =IF(AND(K4*L4*30*N4>H4/J4,I4=""),"לרכוש","לא לרכוש") -> לא לרכוש | N4: 1000
A5: ='רשימת מכשור 2015'!A4 -> אנלייזר פחמן אורגני | B5: ='רשימת מכשור 2015'!B4 -> THORNTON | C5: ='רשימת מכשור 2015'!C4 -> 5000 | D5: ='רשימת מכשור 2015'!D4 -> PW פיילוט | E5: ='רשימת מכשור 2015'!E4 -> 1-TOC-1 | F5: ='רשימת מכשור 2015'!F4 -> 50000 | G5: 1 | H5: =G5*F5 -> 50000 | I5: √ | J5: 1 | K5: 1 | L5: 1.5 | M5: =IF(AND(K5*L5*30*N5>H5/J5,I5=""),"לרכוש","לא לרכוש") -> לא לרכוש | N5: 1000 | P5: 3
A6: ='רשימת מכשור 2015'!A5 -> אנלייזר פחמן אורגני | B6: ='רשימת מכשור 2015'!B5 -> Mettler Toledo | C6: ='רשימת מכשור 2015'!C5 -> 5000TOC | D6: ='רשימת מכשור 2015'!D5 -> PW STORAGE 2500 | E6: ='רשימת מכשור 2015'!E5 -> 1-1-606-TOC-001 | F6: ='רשימת מכשור 2015'!F5 -> 50000 | G6: 1 | H6: =G6*F6 -> 50000 | I6: √ | J6: 1 | K6: 1 | L6: 1.5 | M6: =IF(AND(K6*L6*30*N6>H6/J6,I6=""),"לרכוש","לא לרכוש") -> לא לרכוש | N6: 1000 | P6: 3
A7: ='רשימת מכשור 2015'!A6 -> אנלייזר פחמן אורגני | B7: ='רשימת מכשור 2015'!B6 -> METTLER TOLEDO | C7: ='רשימת מכשור 2015'!C6 -> 5000TOC | D7: ='רשימת מכשור 2015'!D6 -> WFI-PRODUCTION/STORAGE | E7: ='רשימת מכשור 2015'!E6 -> 1-1-25-TOC-1 | F7: ='רשימת מכשור 2015'!F6 -> 50000 | G7: 1 | H7: =G7*F7 -> 50000 | I7: √ | J7: 1 | K7: 1 | L7: 1.5 | M7: =IF(AND(K7*L7*30*N7>H7/J7,I7=""),"לרכוש","לא לרכוש") -> לא לרכוש | N7: 1000 | P7: 3
A8: ='רשימת מכשור 2015'!A7 -> multi chanel | B8: ='רשימת מכשור 2015'!B7 -> Mettler Toledo | C8: ='רשימת מכשור 2015'!C7 -> 770MAX | D8: ='רשימת מכשור 2015'!D7 -> 5000 | E8: ='רשימת מכשור 2015'!E7 -> N/A | F8: ='רשימת מכשור 2015'!F7 -> 10000 | G8: 1 | H8: 20000 | I8: √ | J8: 1 | K8: 1 | L8: 1.5 | M8: לא לרכוש | N8: 1000 | P8: 5
A9: ='רשימת מכשור 2015'!A8 -> multi chanel | B9: ='רשימת מכשור 2015'!B8 -> Mettler Toledo | C9: ='רשימת מכשור 2015'!C8 -> 770MAX | D9: ='רשימת מכשור 2015'!D8 -> 2500 | E9: ='רשימת מכשור 2015'!E8 -> N/A | F9: ='רשימת מכשור 2015'!F8 -> 10000 | G9: 1 | H9: =G9*F9 -> 10000 | I9: √ | J9: 1 | K9: 1 | L9: 1.5 | M9: =IF(AND(K9*L9*30*N9>H9/J9,I9=""),"לרכוש","לא לרכוש") -> לא לרכוש | N9: 1000 | P9: 5
A10: ='רשימת מכשור 2015'!A9 -> אנלייזר קשיות | B10: ='רשימת מכשור 2015'!B9 -> ABB ISRAEL | C10: ='רשימת מכשור 2015'!C9 -> AW101/.1.2.1.1 | D10: ='רשימת מכשור 2015'!D9 -> HSW | E10: ='רשימת מכשור 2015'!E9 -> 1-1-57-HIC-1 | F10: ='רשימת מכשור 2015'!F9 -> 18000 | G10: 1 | H10: 18000 | J10: 1 | K10: 1 | N10: 1000 | P10: 1
A11: ='רשימת מכשור 2015'!A10 -> מד זרימה | B11: ='רשימת מכשור 2015'!B10 -> Liquid Controls Sponsler | C11: ='רשימת מכשור 2015'!C10 -> SP3/4-CS-PHL-3/4G-6MCIX3A | D11: ='רשימת מכשור 2015'!D10 -> CDI | E11: ='רשימת מכשור 2015'!E10 -> 1-1-134-FIC-1 | F11: ='רשימת מכשור 2015'!F10 -> 14000 | G11: 1 | H11: =G11*F11 -> 14000 | I11: √ | J11: 1 | K11: 1 | L11: 1.5 | M11: =IF(AND(K11*L11*30*N11>H11/J11,I11=""),"לרכוש","לא לרכוש") -> לא לרכוש | N11: 1000 | P11: 3
A12: ='רשימת מכשור 2015'!A11 -> מד זרימה | B12: ='רשימת מכשור 2015'!B11 -> Liquid Controls Sponsler | C12: ='רשימת מכשור 2015'!C11 -> SP3/4-CS-PHL-3/4G-6MCIX3A | D12: ='רשימת מכשור 2015'!D11 -> CDI | E12: ='רשימת מכשור 2015'!E11 -> 1-1-134-FIC-3 | F12: ='רשימת מכשור 2015'!F11 -> 14000 | G12: 1 | H12: =G12*F12 -> 14000 | I12: √ | J12: 1 | K12: 1 | L12: 1.5 | M12: =IF(AND(K12*L12*30*N12>H12/J12,I12=""),"לרכוש","לא לרכוש") -> לא לרכוש | N12: 1000 | P12: 3
A13: ='רשימת מכשור 2015'!A12 -> משדר זרימה | B13: ='רשימת מכשור 2015'!B12 -> Liquid Controls Sponsler | C13: ='רשימת מכשור 2015'!C12 -> SP3/4-CS-PHL -3/4G-6MCIX3A | D13: ='רשימת מכשור 2015'!D12 -> PW PRODUCTION 2500 | E13: ='רשימת מכשור 2015'!E12 -> 1-1-604-FIT-001 | F13: ='רשימת מכשור 2015'!F12 -> 12000 | G13: 1 | H13: =G13*F13 -> 12000 | I13: √ | J13: 1 | K13: 0 | L13: 1.5 | M13: =IF(AND(K13*L13*30*N13>H13/J13,I13=""),"לרכוש","לא לרכוש") -> לא לרכוש | N13: 1000 | P13: 3
A14: ='רשימת מכשור 2015'!A13 -> מד מפלס | B14: ='רשימת מכשור 2015'!B13 -> E+H | C14: ='רשימת מכשור 2015'!C13 -> MICROPILOT M FMR245-AETEJAA2AA | D14: ='רשימת מכשור 2015'!D13 -> NaOH | E14: ='רשימת מכשור 2015'!E13 -> 1-1-5-LC-1 | F14: ='רשימת מכשור 2015'!F13 -> 120000 | G14: 1 | H14: 12000 | J14: 1 | K14: 1 | L14: 1.5 | M14: =IF(AND(K14*L14*30*N14>H14/J14,I14=""),"לרכוש","לא לרכוש") -> לרכוש | N14: 1000 | P14: 2
A15: ='רשימת מכשור 2015'!A14 -> מד מפלס | B15: ='רשימת מכשור 2015'!B14 -> E+H | C15: ='רשימת מכשור 2015'!C14 -> MICROPILOT M FMR245-AETEJAA2AA | D15: ='רשימת מכשור 2015'!D14 -> ACID | E15: ='רשימת מכשור 2015'!E14 -> 1-1-141-LC-1 | F15: ='רשימת מכשור 2015'!F14 -> 120000 | G15: 1 | H15: 12000 | J15: 1 | K15: 1 | L15: 1.5 | M15: =IF(AND(K15*L15*30*N15>H15/J15,I15=""),"לרכוש","לא לרכוש") -> לרכוש | N15: 1000 | P15: 2
A16: ='רשימת מכשור 2015'!A15 -> מד מפלס | B16: ='רשימת מכשור 2015'!B15 -> E+H | C16: ='רשימת מכשור 2015'!C15 -> LEVELFLEX M FMP43-AS5TDJB21A2B | D16: ='רשימת מכשור 2015'!D15 -> WFI-PRODUCTION/STORAGE | E16: ='רשימת מכשור 2015'!E15 -> 25-LT-001 | F16: ='רשימת מכשור 2015'!F15 -> 12000 | G16: 1 | H16: =G16*F16 -> 12000 | J16: 1 | K16: 1 | L16: 1.5 | M16: =IF(AND(K16*L16*30*N16>H16/J16,I16=""),"לרכוש","לא לרכוש") -> לרכוש | N16: 1000 | P16: 1
A17: ='רשימת מכשור 2015'!A16 -> מד מפלס | B17: ='רשימת מכשור 2015'!B16 -> E+H | C17: ='רשימת מכשור 2015'!C16 -> LEVELFLEX M FMP41C-AATDKB21A2A | D17: ='רשימת מכשור 2015'!D16 -> SW SYSTEM | E17: ='רשימת מכשור 2015'!E16 -> 1-1-132-LIC-1 | F17: ='רשימת מכשור 2015'!F16 -> 12000 | G17: 1 | H17: =G17*F17 -> 12000 | J17: 1 | K17: 1 | L17: 1.5 | M17: =IF(AND(K17*L17*30*N17>H17/J17,I17=""),"לרכוש","לא לרכוש") -> לרכוש | N17: 1000 | P17: 1
A18: ='רשימת מכשור 2015'!A17 -> משדר לחץ | B18: ='רשימת מכשור 2015'!B17 -> LABOM | C18: ='רשימת מכשור 2015'!C17 -> LABOM - CV3110 | D18: ='רשימת מכשור 2015'!D17 -> צנטרפוגה | E18: ='רשימת מכשור 2015'!E17 -> PIAL 02-9-020 | F18: ='רשימת מכשור 2015'!F17 -> 10000 | G18: 1 | H18: =G18*F18 -> 10000 | J18: 1 | K18: 1 | L18: 1.5 | M18: =IF(AND(K18*L18*30*N18>H18/J18,I18=""),"לרכוש","לא לרכוש") -> לרכוש | N18: 1000 | P18: 3
A19: ='רשימת מכשור 2015'!A18 -> משדר לחץ | B19: ='רשימת מכשור 2015'!B18 -> LABOM | C19: ='רשימת מכשור 2015'!C18 -> LABOM - CV3110 | D19: ='רשימת מכשור 2015'!D18 -> צנטרפוגה | E19: ='רשימת מכשור 2015'!E18 -> PIAL 02-9-534 | F19: ='רשימת מכשור 2015'!F18 -> 10000 | G19: 1 | H19: =G19*F19 -> 10000 | J19: 1 | K19: 1 | L19: 1.5 | M19: =IF(AND(K19*L19*30*N19>H19/J19,I19=""),"לרכוש","לא לרכוש") -> לרכוש | N19: 1000 | P19: 3
A20: ='רשימת מכשור 2015'!A19 -> multi chanel | B20: ='רשימת מכשור 2015'!B19 -> THORNTON | C20: ='רשימת מכשור 2015'!C19 -> 770 max | D20: ='רשימת מכשור 2015'!D19 -> PW פיילוט | E20: ='רשימת מכשור 2015'!E19 -> 0 | F20: ='רשימת מכשור 2015'!F19 -> 10000 | G20: 1 | H20: =G20*F20 -> 10000 | I20: √ | J20: 1 | K20: 1 | L20: 1 | M20: =IF(AND(K20*L20*30*N20>H20/J20,I20=""),"לרכוש","לא לרכוש") -> לא לרכוש | N20: 1000 | P20: 5
A21: ='רשימת מכשור 2015'!A20 -> מד כלור | B21: ='רשימת מכשור 2015'!B20 -> E+H | C21: ='רשימת מכשור 2015'!C20 -> transmitter : liquisys m CCM253-EK8005 FLOWFIT-W CCA250 | D21: ='רשימת מכשור 2015'!D20 -> CLW | E21: ='רשימת מכשור 2015'!E20 -> 1-1-1-CLIC-1 | F21: ='רשימת מכשור 2015'!F20 -> 7000 | G21: 1 | H21: =G21*F21 -> 7000 | J21: 1 | K21: 1 | L21: 1.5 | M21: =IF(AND(K21*L21*30*N21>H21/J21,I21=""),"לרכוש","לא לרכוש") -> לרכוש | N21: 1000 | P21: 1
A22: ='רשימת מכשור 2015'!A21 -> מד מפלס | B22: ='רשימת מכשור 2015'!B21 -> E+H | C22: ='רשימת מכשור 2015'!C21 -> LIQUICAP M FMI52-A1BTDJA2A1A | D22: ='רשימת מכשור 2015'!D21 -> CLW | E22: ='רשימת מכשור 2015'!E21 -> 1-1-1-LC-1 | F22: ='רשימת מכשור 2015'!F21 -> 10000 | G22: 1 | H22: =G22*F22 -> 10000 | J22: 1 | K22: 1 | L22: 1.5 | M22: =IF(AND(K22*L22*30*N22>H22/J22,I22=""),"לרכוש","לא לרכוש") -> לרכוש | N22: 1000 | P22: 1
A23: ='רשימת מכשור 2015'!A22 -> מד מפלס | B23: ='רשימת מכשור 2015'!B22 -> E+H | C23: ='רשימת מכשור 2015'!C22 -> LIQUICAP M FMI52-A1BTDJA2A1A | D23: ='רשימת מכשור 2015'!D22 -> HSW | E23: ='רשימת מכשור 2015'!E22 -> 1-1-57-LC-1 | F23: ='רשימת מכשור 2015'!F22 -> 10000 | G23: 1 | H23: 10000 | J23: 1 | K23: 1 | L23: 1.5 | M23: =IF(AND(K23*L23*30*N23>H23/J23,I23=""),"לרכוש","לא לרכוש") -> לרכוש | N23: 1000 | P23: 1
A24: ='רשימת מכשור 2015'!A23 -> multi chanel | B24: ='רשימת מכשור 2015'!B23 -> torenton | C24: ='רשימת מכשור 2015'!C23 -> torenton | D24: ='רשימת מכשור 2015'!D23 -> WFI-PRODUCTION/STORAGE | E24: ='רשימת מכשור 2015'!E23 -> 25-CIT-1 | F24: ='רשימת מכשור 2015'!F23 -> 10000 | G24: 1 | H24: =G24*F24 -> 10000 | I24: √ | J24: 1 | K24: 1 | L24: 1.2 | M24: =IF(AND(K24*L24*30*N24>H24/J24,I24=""),"לרכוש","לא לרכוש") -> לא לרכוש | N24: 1000 | P24: 5
A25: ='רשימת מכשור 2015'!A24 -> משדר לחץ | B25: ='רשימת מכשור 2015'!B24 -> LABOM | C25: ='רשימת מכשור 2015'!C24 -> LABOM - CV3110 | D25: ='רשימת מכשור 2015'!D24 -> צנטרפוגה | E25: ='רשימת מכשור 2015'!E24 -> PIC 02-9-047 | F25: ='רשימת מכשור 2015'!F24 -> 10000 | G25: 1 | H25: =G25*F25 -> 10000 | J25: 1 | K25: 1 | L25: 1.5 | M25: =IF(AND(K25*L25*30*N25>H25/J25,I25=""),"לרכוש","לא לרכוש") -> לרכוש | N25: 1000 | P25: 3
A26: ='רשימת מכשור 2015'!A25 -> מד זרימה | B26: ='רשימת מכשור 2015'!B25 -> ABB ISRAEL | C26: ='רשימת מכשור 2015'!C25 -> ABB - FEH311 | D26: ='רשימת מכשור 2015'!D25 -> צנטרפוגה | E26: ='רשימת מכשור 2015'!E25 -> FIC 02-9-041 | F26: ='רשימת מכשור 2015'!F25 -> 9133 | G26: 1 | H26: =G26*F26 -> 9133 | J26: 1 | K26: 1 | L26: 1.5 | M26: =IF(AND(K26*L26*30*N26>H26/J26,I26=""),"לרכוש","לא לרכוש") -> לרכוש | N26: 1000 | P26: 2
A27: ='רשימת מכשור 2015'!A26 -> משדר חמצן | B27: ='רשימת מכשור 2015'!B26 -> Drager | C27: ='רשימת מכשור 2015'!C26 -> polytron 7000 | D27: ='רשימת מכשור 2015'!D26 -> GAS phase cell bank | E27: ='רשימת מכשור 2015'!E26 -> 1-2-2010-OM-2 | F27: ='רשימת מכשור 2015'!F26 -> 7500 | G27: 1 | H27: =G27*F27 -> 7500 | J27: 1 | K27: 1 | L27: 1 | M27: =IF(AND(K27*L27*30*N27>H27/J27,I27=""),"לרכוש","לא לרכוש") -> לרכוש | N27: 1000 | P27: 1
A28: ='רשימת מכשור 2015'!A27 -> מד כלור | B28: ='רשימת מכשור 2015'!B27 -> E+H | C28: ='רשימת מכשור 2015'!C27 -> Element : ccs140 transmitter : liquisys m cell : flowfit cca250 | D28: ='רשימת מכשור 2015'!D27 -> PRETREATMENT SYSTEM | E28: ='רשימת מכשור 2015'!E27 -> 1-1-131-CLIC-1 | F28: ='רשימת מכשור 2015'!F27 -> 7000 | G28: 1 | H28: =G28*F28 -> 7000 | J28: 1 | K28: 1 | L28: 1.5 | M28: =IF(AND(K28*L28*30*N28>H28/J28,I28=""),"לרכוש","לא לרכוש") -> לרכוש | N28: 1000 | P28: 2
A29: ='רשימת מכשור 2015'!A28 -> אלקטרודת מוליכות | B29: ='רשימת מכשור 2015'!B28 -> E+H | C29: ='רשימת מכשור 2015'!C28 -> Element : cls21-c1e4a Transmitter : liquisys m clm253-cd8005 | D29: ='רשימת מכשור 2015'!D28 -> PRETREATMENT SYSTEM | E29: ='רשימת מכשור 2015'!E28 -> 1-1-131-CIT 1 | F29: ='רשימת מכשור 2015'!F28 -> 7000 | G29: 1 | H29: =G29*F29 -> 7000 | J29: 1 | K29: 1 | L29: 1.5 | M29: =IF(AND(K29*L29*30*N29>H29/J29,I29=""),"לרכוש","לא לרכוש") -> לרכוש | N29: 1000 | P29: 2 | Q29: ניתן לישם פתרון ידני
A30: ='רשימת מכשור 2015'!A29 -> אלקטרודת מוליכות | B30: ='רשימת מכשור 2015'!B29 -> Mettler Toledo | C30: ='רשימת מכשור 2015'!C29 -> Inpro 7108 1.5"TC 5200800 M400 | D30: ='רשימת מכשור 2015'!D29 -> MEDIA | E30: ='רשימת מכשור 2015'!E29 -> 1-1-56-CIC-1 | F30: ='רשימת מכשור 2015'!F29 -> 4000 | G30: 1 | H30: =G30*F30 -> 4000 | I30: √ | J30: 1 | K30: 1 | L30: 1.5 | M30: =IF(AND(K30*L30*30*N30>H30/J30,I30=""),"לרכוש","לא לרכוש") -> לא לרכוש | N30: 1000 | P30: 1 | Q30: פוגע באיכות הסביבה ולכן סומן כמשבית
A31: ='רשימת מכשור 2015'!A30 -> מד רדוקס | B31: ='רשימת מכשור 2015'!B30 -> EUTECH INSTRUMENT | C31: ='רשימת מכשור 2015'!C30 -> Sensor: Pt4805-DPA-SC-S8 Transmiter: ALPHA pH800 | D31: ='רשימת מכשור 2015'!D30 -> SW SYSTEM | E31: ='רשימת מכשור 2015'!E30 -> 1-1-132-ORP-1 | F31: ='רשימת מכשור 2015'!F30 -> 7000 | G31: 1 | H31: =G31*F31 -> 7000 | J31: 1 | K31: 1 | L31: 1.5 | M31: =IF(AND(K31*L31*30*N31>H31/J31,I31=""),"לרכוש","לא לרכוש") -> לרכוש | N31: 1000 | P31: 2
A32: ='רשימת מכשור 2015'!A31 -> מד לחץ | B32: ='רשימת מכשור 2015'!B31 -> LABOM | C32: ='רשימת מכשור 2015'!C31 -> LABOM - BH4200 | D32: ='רשימת מכשור 2015'!D31 -> צנטרפוגה | E32: ='רשימת מכשור 2015'!E31 -> PI 02-9-019 | F32: ='רשימת מכשור 2015'!F31 -> 6708 | G32: 1 | H32: =G32*F32 -> 6708 | J32: 1 | K32: 0 | L32: 1.5 | M32: =IF(AND(K32*L32*30*N32>H32/J32,I32=""),"לרכוש","לא לרכוש") -> לא לרכוש | N32: 1000 | P32: 1
A33: ='רשימת מכשור 2015'!A32 -> מד רעידות | B33: ='רשימת מכשור 2015'!B32 -> GEAיצור עצמי | C33: ='רשימת מכשור 2015'!C32 -> HW - sensor messtechnik pch | D33: ='רשימת מכשור 2015'!D32 -> צנטרפוגה | E33: ='רשימת מכשור 2015'!E32 -> NAH/HH01-9-018 | F33: ='רשימת מכשור 2015'!F32 -> 6615 | G33: 1 | H33: =G33*F33 -> 6615 | J33: 1 | K33: 1 | L33: 1.5 | M33: =IF(AND(K33*L33*30*N33>H33/J33,I33=""),"לרכוש","לא לרכוש") -> לרכוש | N33: 1000 | P33: 1
A34: ='רשימת מכשור 2015'!A33 -> משדר לחץ | B34: ='רשימת מכשור 2015'!B33 -> E+H | C34: ='רשימת מכשור 2015'!C33 -> PMP46-RE13SBJPGD | D34: ='רשימת מכשור 2015'!D33 -> PW STORAGE 2500 | E34: ='רשימת מכשור 2015'!E33 -> 1-1-606-PIT-007 | F34: ='רשימת מכשור 2015'!F33 -> 6000 | G34: 1 | H34: =G34*F34 -> 6000 | I34: √ | J34: 1 | K34: 1 | L34: 1 | M34: =IF(AND(K34*L34*30*N34>H34/J34,I34=""),"לרכוש","לא לרכוש") -> לא לרכוש | N34: 1000 | P34: 1
A35: ='רשימת מכשור 2015'!A34 -> משדר לחץ | B35: ='רשימת מכשור 2015'!B34 -> Carabar M | C35: ='רשימת מכשור 2015'!C34 -> D800AB0112A | D35: ='רשימת מכשור 2015'!D34 -> WFI-PRODUCTION/STORAGE | E35: ='רשימת מכשור 2015'!E34 -> 25-PIC-1 | F35: ='רשימת מכשור 2015'!F34 -> 6000 | G35: 1 | H35: =G35*F35 -> 6000 | I35: √ | J35: 1 | K35: 1 | L35: 1.2 | M35: =IF(AND(K35*L35*30*N35>H35/J35,I35=""),"לרכוש","לא לרכוש") -> לא לרכוש | N35: 1000 | P35: 1
A36: ='רשימת מכשור 2015'!A35 -> משדר לחץ | B36: ='רשימת מכשור 2015'!B35 -> E+H | C36: ='רשימת מכשור 2015'!C35 -> CERABAR M PMC45 | D36: ='רשימת מכשור 2015'!D35 -> RO PRODUCTION | E36: ='רשימת מכשור 2015'!E35 -> 1-1-133-PIC-2 | F36: ='רשימת מכשור 2015'!F35 -> 6000 | G36: 1 | H36: =G36*F36 -> 6000 | I36: √ | J36: 1 | K36: 1 | L36: 1.5 | M36: =IF(AND(K36*L36*30*N36>H36/J36,I36=""),"לרכוש","לא לרכוש") -> לא לרכוש | N36: 1000 | P36: 1
A37: ='רשימת מכשור 2015'!A36 -> משדר לחץ | B37: ='רשימת מכשור 2015'!B36 -> E+H | C37: ='רשימת מכשור 2015'!C36 -> CB012C01024 | D37: ='רשימת מכשור 2015'!D36 -> RO PRODUCTION | E37: ='רשימת מכשור 2015'!E36 -> 1-1-133-PIC-6 | F37: ='רשימת מכשור 2015'!F36 -> 6000 | G37: 1 | H37: =G37*F37 -> 6000 | J37: 1 | K37: 1 | L37: 1.5 | M37: =IF(AND(K37*L37*30*N37>H37/J37,I37=""),"לרכוש","לא לרכוש") -> לרכוש | N37: 1000 | P37: 2
A38: ='רשימת מכשור 2015'!A37 -> מד ובקר לחץ | B38: ='רשימת מכשור 2015'!B37 -> E+H | C38: ='רשימת מכשור 2015'!C37 -> CB012C01024 | D38: ='רשימת מכשור 2015'!D37 -> RO PRODUCTION | E38: ='רשימת מכשור 2015'!E37 -> 1-1-133-PIC-1 | F38: ='רשימת מכשור 2015'!F37 -> 6000 | G38: 1 | H38: =G38*F38 -> 6000 | J38: 1 | K38: 1 | L38: 1.5 | M38: =IF(AND(K38*L38*30*N38>H38/J38,I38=""),"לרכוש","לא לרכוש") -> לרכוש | N38: 1000 | P38: 2
A39: ='רשימת מכשור 2015'!A38 -> משדר לחץ | B39: ='רשימת מכשור 2015'!B38 -> E+H | C39: ='רשימת מכשור 2015'!C38 -> CERABAR M PMP46-RE17P1JPDGD | D39: ='רשימת מכשור 2015'!D38 -> MEDIA | E39: ='רשימת מכשור 2015'!E38 -> 1-1-56-PC-1 | F39: ='רשימת מכשור 2015'!F38 -> 6000 | G39: 1 | H39: =G39*F39 -> 6000 | I39: √ | J39: 1 | K39: 1 | L39: 1.5 | M39: =IF(AND(K39*L39*30*N39>H39/J39,I39=""),"לרכוש","לא לרכוש") -> לא לרכוש | N39: 1000 | P39: 2
A40: ='רשימת מכשור 2015'!A39 -> משדר לחץ | B40: ='רשימת מכשור 2015'!B39 -> E+H | C40: ='רשימת מכשור 2015'!C39 -> CERABAR M PMP46-RE17P1JPDGD | D40: ='רשימת מכשור 2015'!D39 -> MEDIA | E40: ='רשימת מכשור 2015'!E39 -> 1-1-56-PC-2 | F40: ='רשימת מכשור 2015'!F39 -> 6000 | G40: 1 | H40: =G40*F40 -> 6000 | I40: √ | J40: 1 | K40: 1 | L40: 1.5 | M40: =IF(AND(K40*L40*30*N40>H40/J40,I40=""),"לרכוש","לא לרכוש") -> לא לרכוש | N40: 1000 | P40: 2
A41: ='רשימת מכשור 2015'!A40 -> משדר לחץ | B41: ='רשימת מכשור 2015'!B40 -> E+H | C41: ='רשימת מכשור 2015'!C40 -> CERABAR M PMP46-RE13SVJPDGD | D41: ='רשימת מכשור 2015'!D40 -> CRUDE | E41: ='רשימת מכשור 2015'!E40 -> 1-1-28-PC-2 | F41: ='רשימת מכשור 2015'!F40 -> 6000 | G41: 1 | H41: =G41*F41 -> 6000 | I41: √ | J41: 1 | K41: 1 | L41: 1.5 | M41: =IF(AND(K41*L41*30*N41>H41/J41,I41=""),"לרכוש","לא לרכוש") -> לא לרכוש | N41: 1000 | P41: 5
...

Sheet חלקי חילוף מכשור 
D2: רשימת חלקי חילוף מכשור ובקרה
A3: תיאור הציוד | B3: מערכת | C3: מס' Tag | D3: יצרן | E3: דגם | F3: מחיר ב₪ | G3: כמות נדרשת למלאי | H3: סה"כ | I3: קיים במלאי כן/לא | J3: סיכוי לכשל | K3: משבית/ לא משבית | L3: זמן הספקה [חודש] | M3: תוצאת חישוב | N3: המלצה : לרכוש / לא לרכוש | O3: עלות השבתה ליום | P3: האם יש הסכם שירות ? | Q3: הערה
A4: מד עכירות | B4: צנטרפוגה | C4: QIAH 02-9-042 | D4: מודקון / לאמיקו | E4: OPTEK - CONVERTOR MODEL | F4: 70000 | G4: 1 | H4: =G4*F4 -> 70000 | J4: 1 | K4: 0 | L4: 2 | M4: =IF(AND(K4*L4*30*O4>H4/J4,I4=""),"לרכוש","לא לרכוש") -> לא לרכוש | O4: 1000
A5: אנלייזר פחמן אורגני | B5: PW פיילוט | C5: 1-TOC-1 | D5: THORNTON | E5: 5000 | F5: 50000 | G5: 1 | H5: =G5*F5 -> 50000 | I5: √ | J5: 1 | K5: 1 | L5: 1.5 | M5: =IF(AND(K5*L5*30*O5>H5/J5,I5=""),"לרכוש","לא לרכוש") -> לא לרכוש | O5: 1000
A6: אנלייזר פחמן אורגני | B6: PW STORAGE 2500 | C6: 1-1-606-TOC-001 | D6: Mettler Toledo | E6: 5000TOC | F6: 50000 | G6: 1 | H6: =G6*F6 -> 50000 | I6: √ | J6: 1 | K6: 1 | L6: 1.5 | M6: =IF(AND(K6*L6*30*O6>H6/J6,I6=""),"לרכוש","לא לרכוש") -> לא לרכוש | O6: 1000
A7: אנלייזר פחמן אורגני | B7: WFI-PRODUCTION/STORAGE | C7: 1-1-25-TOC-1 | D7: METTLER TOLEDO | E7: 5000TOC | F7: 50000 | G7: 1 | H7: =G7*F7 -> 50000 | I7: √ | J7: 1 | K7: 1 | L7: 1.5 | M7: =IF(AND(K7*L7*30*O7>H7/J7,I7=""),"לרכוש","לא לרכוש") -> לא לרכוש | O7: 1000
A8: multi chanel | B8: 5000 | C8: N/A | D8: Mettler Toledo | E8: 770MAX | F8: 10000 | G8: 1 | H8: 20000 | I8: √ | J8: 1 | K8: 1 | L8: 1.5 | M8: לא לרכוש | O8: 1000
A9: multi chanel | B9: 2500 | C9: N/A | D9: Mettler Toledo | E9: 770MAX | F9: 10000 | G9: 1 | H9: =G9*F9 -> 10000 | I9: √ | J9: 1 | K9: 1 | L9: 1.5 | M9: =IF(AND(K9*L9*30*O9>H9/J9,I9=""),"לרכוש","לא לרכוש") -> לא לרכוש | O9: 1000
A10: אנלייזר קשיות | B10: HSW | C10: 1-1-57-HIC-1 | D10: ABB ISRAEL | E10: AW101/.1.2.1.1 | F10: 18000 | G10: 1 | H10: 18000 | J10: 1 | K10: 1 | O10: 1000
A11: מד זרימה | B11: CDI | C11: 1-1-134-FIC-1 | D11: Liquid Controls Sponsler | E11: SP3/4-CS-PHL-3/4G-6MCIX3A | F11: 14000 | G11: 1 | H11: =G11*F11 -> 14000 | I11: √ | J11: 1 | K11: 1 | L11: 1.5 | M11: =IF(AND(K11*L11*30*O11>H11/J11,I11=""),"לרכוש","לא לרכוש") -> לא לרכוש | O11: 1000
A12: מד זרימה | B12: CDI | C12: 1-1-134-FIC-3 | D12: Liquid Controls Sponsler | E12: SP3/4-CS-PHL-3/4G-6MCIX3A | F12: 14000 | G12: 1 | H12: =G12*F12 -> 14000 | I12: √ | J12: 1 | K12: 1 | L12: 1.5 | M12: =IF(AND(K12*L12*30*O12>H12/J12,I12=""),"לרכוש","לא לרכוש") -> לא לרכוש | O12: 1000
A13: משדר זרימה | B13: PW PRODUCTION 2500 | C13: 1-1-604-FIT-001 | D13: Liquid Controls Sponsler | E13: SP3/4-CS-PHL -3/4G-6MCIX3A | F13: 12000 | G13: 1 | H13: =G13*F13 -> 12000 | I13: √ | J13: 1 | K13: 0 | L13: 1.5 | M13: =IF(AND(K13*L13*30*O13>H13/J13,I13=""),"לרכוש","לא לרכוש") -> לא לרכוש | O13: 1000
A14: מד מפלס | B14: NaOH | C14: 1-1-5-LC-1 | D14: E+H | E14: MICROPILOT M FMR245-AETEJAA2AA | F14: 120000 | G14: 1 | H14: 12000 | J14: 1 | K14: 1 | L14: 1.5 | M14: =IF(AND(K14*L14*30*O14>H14/J14,I14=""),"לרכוש","לא לרכוש") -> לרכוש | O14: 1000
A15: מד מפלס | B15: ACID | C15: 1-1-141-LC-1 | D15: E+H | E15: MICROPILOT M FMR245-AETEJAA2AA | F15: 120000 | G15: 1 | H15: 12000 | J15: 1 | K15: 1 | L15: 1.5 | M15: =IF(AND(K15*L15*30*O15>H15/J15,I15=""),"לרכוש","לא לרכוש") -> לרכוש | O15: 1000
A16: מד מפלס | B16: WFI-PRODUCTION/STORAGE | C16: 25-LT-001 | D16: E+H | E16: LEVELFLEX M FMP43-AS5TDJB21A2B | F16: 12000 | G16: 1 | H16: =G16*F16 -> 12000 | J16: 1 | K16: 1 | L16: 1.5 | M16: =IF(AND(K16*L16*30*O16>H16/J16,I16=""),"לרכוש","לא לרכוש") -> לרכוש | O16: 1000
A17: מד מפלס | B17: SW SYSTEM | C17: 1-1-132-LIC-1 | D17: E+H | E17: LEVELFLEX M FMP41C-AATDKB21A2A | F17: 12000 | G17: 1 | H17: =G17*F17 -> 12000 | J17: 1 | K17: 1 | L17: 1.5 | M17: =IF(AND(K17*L17*30*O17>H17/J17,I17=""),"לרכוש","לא לרכוש") -> לרכוש | O17: 1000
A18: משדר לחץ | B18: צנטרפוגה | C18: PIAL 02-9-020 | D18: LABOM | E18: LABOM - CV3110 | F18: 10000 | G18: 1 | H18: =G18*F18 -> 10000 | J18: 1 | K18: 1 | L18: 1.5 | M18: =IF(AND(K18*L18*30*O18>H18/J18,I18=""),"לרכוש","לא לרכוש") -> לרכוש | O18: 1000
A19: משדר לחץ | B19: צנטרפוגה | C19: PIAL 02-9-534 | D19: LABOM | E19: LABOM - CV3110 | F19: 10000 | G19: 1 | H19: =G19*F19 -> 10000 | I19: √ | J19: 1 | K19: 1 | L19: 1.5 | M19: =IF(AND(K19*L19*30*O19>H19/J19,I19=""),"לרכוש","לא לרכוש") -> לא לרכוש | O19: 1000
A20: multi chanel | B20: PW פיילוט | D20: THORNTON | E20: 770 max | F20: 10000 | G20: 1 | H20: =G20*F20 -> 10000 | I20: √ | J20: 1 | K20: 1 | L20: 1 | M20: =IF(AND(K20*L20*30*O20>H20/J20,I20=""),"לרכוש","לא לרכוש") -> לא לרכוש | O20: 1000
A21: מד כלור | B21: PW PRETREAMENT 2500 | C21: 1-1-605-CL-001 | D21: Prominent | E21: Sensor: CLE3-DMT-5ppm Transmitter: DMT AW 090C10E000 | F21: 10000 | G21: 1 | H21: =G21*F21 -> 10000 | J21: 1 | K21: 1 | L21: 1.5 | M21: =IF(AND(K21*L21*30*O21>H21/J21,I21=""),"לרכוש","לא לרכוש") -> לרכוש | O21: 1000
A22: מד מפלס | B22: CLW | C22: 1-1-1-LC-1 | D22: E+H | E22: LIQUICAP M FMI52-A1BTDJA2A1A | F22: 10000 | G22: 1 | H22: =G22*F22 -> 10000 | J22: 1 | K22: 1 | L22: 1.5 | M22: =IF(AND(K22*L22*30*O22>H22/J22,I22=""),"לרכוש","לא לרכוש") -> לרכוש | O22: 1000
A23: מד מפלס | B23: HSW | C23: 1-1-57-LC-1 | D23: E+H | E23: LIQUICAP M FMI52-A1BTDJA2A1A | F23: 10000 | G23: 1 | H23: 10000 | J23: 1 | K23: 1 | L23: 1.5 | M23: =IF(AND(K23*L23*30*O23>H23/J23,I23=""),"לרכוש","לא לרכוש") -> לרכוש | O23: 1000
A24: multi chanel | B24: WFI-PRODUCTION/STORAGE | C24: 25-CIT-1 | D24: torenton | E24: torenton | F24: 10000 | G24: 1 | H24: =G24*F24 -> 10000 | I24: √ | J24: 1 | K24: 1 | L24: 1.2 | M24: =IF(AND(K24*L24*30*O24>H24/J24,I24=""),"לרכוש","לא לרכוש") -> לא לרכוש | O24: 1000
A25: משדר לחץ | B25: צנטרפוגה | C25: PIC 02-9-047 | D25: LABOM | E25: LABOM - CV3110 | F25: 9300 | G25: 1 | H25: =G25*F25 -> 9300 | J25: 1 | K25: 1 | L25: 1.5 | M25: =IF(AND(K25*L25*30*O25>H25/J25,I25=""),"לרכוש","לא לרכוש") -> לרכוש | O25: 1000
A26: מד זרימה | B26: צנטרפוגה | C26: FIC 02-9-041 | D26: ABB ISRAEL | E26: ABB - FEH311 | F26: 9133 | G26: 1 | H26: =G26*F26 -> 9133 | J26: 1 | K26: 1 | L26: 1.5 | M26: =IF(AND(K26*L26*30*O26>H26/J26,I26=""),"לרכוש","לא לרכוש") -> לרכוש | O26: 1000
A27: משדר חמצן | B27: GAS phase cell bank | C27: 1-2-2010-OM-2 | D27: Drager | E27: polytron 7000 | F27: 7500 | G27: 1 | H27: =G27*F27 -> 7500 | J27: 1 | K27: 1 | L27: 1 | M27: =IF(AND(K27*L27*30*O27>H27/J27,I27=""),"לרכוש","לא לרכוש") -> לרכוש | O27: 1000
A28: מד כלור | B28: CLW | C28: 1-1-1-CLIC-1 | D28: E+H | E28: transmitter : liquisys m CCM253-EK8005 FLOWFIT-W CCA250 | F28: 7000 | G28: 1 | H28: =G28*F28 -> 7000 | J28: 1 | K28: 1 | L28: 1.5 | M28: =IF(AND(K28*L28*30*O28>H28/J28,I28=""),"לרכוש","לא לרכוש") -> לרכוש | O28: 1000
A29: מד כלור | B29: PRETREATMENT SYSTEM | C29: 1-1-131-CLIC-1 | D29: E+H | E29: Element : ccs140 transmitter : liquisys m cell : flowfit cca250 | F29: 7000 | G29: 1 | H29: =G29*F29 -> 7000 | J29: 1 | K29: 1 | L29: 1.5 | M29: =IF(AND(K29*L29*30*O29>H29/J29,I29=""),"לרכוש","לא לרכוש") -> לרכוש | O29: 1000 | Q29: ניתן לישם פתרון ידני
A30: אלקטרודת מוליכות | B30: PRETREATMENT SYSTEM | C30: 1-1-131-CIT 1 | D30: E+H | E30: Element : cls21-c1e4a Transmitter : liquisys m clm253-cd8005 | F30: 7000 | G30: 1 | H30: =G30*F30 -> 7000 | I30: √ | J30: 1 | K30: 1 | L30: 1.5 | M30: =IF(AND(K30*L30*30*O30>H30/J30,I30=""),"לרכוש","לא לרכוש") -> לא לרכוש | O30: 1000 | Q30: פוגע באיכות הסביבה ולכן סומן כמשבית
A31: מד רדוקס | B31: SW SYSTEM | C31: 1-1-132-ORP-1 | D31: EUTECH INSTRUMENT | E31: Sensor: Pt4805-DPA-SC-S8 Transmiter: ALPHA pH800 | F31: 7000 | G31: 1 | H31: =G31*F31 -> 7000 | J31: 1 | K31: 1 | L31: 1.5 | M31: =IF(AND(K31*L31*30*O31>H31/J31,I31=""),"לרכוש","לא לרכוש") -> לרכוש | O31: 1000
A32: מד לחץ | B32: צנטרפוגה | C32: PI 02-9-019 | D32: LABOM | E32: LABOM - BH4200 | F32: 6708 | G32: 1 | H32: =G32*F32 -> 6708 | J32: 1 | K32: 0 | L32: 1.5 | M32: =IF(AND(K32*L32*30*O32>H32/J32,I32=""),"לרכוש","לא לרכוש") -> לא לרכוש | O32: 1000
A33: מד רעידות | B33: צנטרפוגה | C33: NAH/HH01-9-018 | D33: GEAיצור עצמי | E33: HW - sensor messtechnik pch | F33: 6615 | G33: 1 | H33: =G33*F33 -> 6615 | J33: 1 | K33: 1 | L33: 1.5 | M33: =IF(AND(K33*L33*30*O33>H33/J33,I33=""),"לרכוש","לא לרכוש") -> לרכוש | O33: 1000
A34: משדר לחץ | B34: PW STORAGE 2500 | C34: 1-1-606-PIT-007 | D34: E+H | E34: PMP46-RE13SBJPGD | F34: 6000 | G34: 1 | H34: =G34*F34 -> 6000 | I34: √ | J34: 1 | K34: 1 | L34: 1 | M34: =IF(AND(K34*L34*30*O34>H34/J34,I34=""),"לרכוש","לא לרכוש") -> לא לרכוש | O34: 1000 | Q34: טעות, לתקן בהזדמנות
A35: משדר לחץ | B35: WFI-PRODUCTION/STORAGE | C35: 25-PIC-1 | D35: Carabar M | E35: D800AB0112A | F35: 6000 | G35: 1 | H35: =G35*F35 -> 6000 | I35: √ | J35: 1 | K35: 1 | L35: 1.2 | M35: =IF(AND(K35*L35*30*O35>H35/J35,I35=""),"לרכוש","לא לרכוש") -> לא לרכוש | O35: 1000
A36: משדר לחץ | B36: RO PRODUCTION | C36: 1-1-133-PIC-2 | D36: E+H | E36: CERABAR M PMC45 | F36: 6000 | G36: 1 | H36: =G36*F36 -> 6000 | I36: √ | J36: 1 | K36: 1 | L36: 1.5 | M36: =IF(AND(K36*L36*30*O36>H36/J36,I36=""),"לרכוש","לא לרכוש") -> לא לרכוש | O36: 1000
A37: משדר לחץ | B37: RO PRODUCTION | C37: 1-1-133-PIC-6 | D37: E+H | E37: CB012C01024 | F37: 6000 | G37: 1 | H37: =G37*F37 -> 6000 | J37: 1 | K37: 1 | L37: 1.5 | M37: =IF(AND(K37*L37*30*O37>H37/J37,I37=""),"לרכוש","לא לרכוש") -> לרכוש | O37: 1000
A38: מד ובקר לחץ | B38: RO PRODUCTION | C38: 1-1-133-PIC-1 | D38: E+H | E38: CB012C01024 | F38: 6000 | G38: 1 | H38: =G38*F38 -> 6000 | J38: 1 | K38: 1 | L38: 1.5 | M38: =IF(AND(K38*L38*30*O38>H38/J38,I38=""),"לרכוש","לא לרכוש") -> לרכוש | O38: 1000
A39: משדר לחץ | B39: MEDIA | C39: 1-1-56-PC-1 | D39: E+H | E39: CERABAR M PMP46-RE17P1JPDGD | F39: 6000 | G39: 1 | H39: =G39*F39 -> 6000 | I39: √ | J39: 1 | K39: 1 | L39: 1.5 | M39: =IF(AND(K39*L39*30*O39>H39/J39,I39=""),"לרכוש","לא לרכוש") -> לא לרכוש | O39: 1000
A40: משדר לחץ | B40: MEDIA | C40: 1-1-56-PC-2 | D40: E+H | E40: CERABAR M PMP46-RE17P1JPDGD | F40: 6000 | G40: 1 | H40: =G40*F40 -> 6000 | I40: √ | J40: 1 | K40: 1 | L40: 1.5 | M40: =IF(AND(K40*L40*30*O40>H40/J40,I40=""),"לרכוש","לא לרכוש") -> לא לרכוש | O40: 1000
A41: משדר לחץ | B41: CRUDE | C41: 1-1-28-PC-2 | D41: E+H | E41: CERABAR M PMP46-RE13SVJPDGD | F41: 6000 | G41: 1 | H41: =G41*F41 -> 6000 | I41: √ | J41: 1 | K41: 1 | L41: 1.5 | M41: =IF(AND(K41*L41*30*O41>H41/J41,I41=""),"לרכוש","לא לרכוש") -> לא לרכוש | O41: 1000
...

Sheet חח מכשור - מלאי מינימום 2015
A2: הרשימה הזו מייצגת את כל המכשור שהיה מותקן בפרוטליקס בשנת 2015 ושימשה כמערכת שיקולים להחלטה על מלאי מינימום ח"ח מכשור. הרשימה אינה עדכנית ולא ניתן להסתמך עליה (עמית 04/02/21) | W2: 0 | X2: 1
A3: תיאור הציוד | B3: יצרן | C3: דגם | D3: מערכת | E3: מס' Tag | F3: מחיר ב₪ | G3: כמות נדרשת למלאי | H3: סה"כ | I3: קיים במלאי כן/לא | J3: סיכוי לכשל | K3: משבית/ לא משבית | L3: זמן הספקה [חודש] | M3: תוצאת חישוב | N3: עלות השבתה ליום | O3: האם יש הסכם שירות ? | P3: כמות מאותו דגם | Q3: האם לחשב כמות מינימום? | R3: מכפלת השיקולים | S3: מספר יחידות למלאי מחושב | T3: מספר יחידות למלאי לאחר דיון | U3: הערה | W3: 0.2 | X3: 3
A4: מד עכירות | B4: מודקון / לאמיקו | C4: OPTEK - CONVERTOR MODEL | D4: צנטרפוגה | E4: QIAH 02-9-042 | F4: 70000 | G4: 1 | H4: =G4*F4 -> 70000 | J4: 1 | K4: 0 | L4: 2 | M4: =IF(AND(K4*L4*30*N4>H4/J4,I4=""),"לרכוש","לא לרכוש") -> לא לרכוש | N4: 1000 | W4: 0.4 | X4: 1
A5: ='רשימת מכשור 2015'!A4 -> אנלייזר פחמן אורגני | B5: ='רשימת מכשור 2015'!B4 -> THORNTON | C5: ='רשימת מכשור 2015'!C4 -> 5000 | D5: ='רשימת מכשור 2015'!D4 -> PW פיילוט | E5: ='רשימת מכשור 2015'!E4 -> 1-TOC-1 | F5: ='רשימת מכשור 2015'!F4 -> 50000 | G5: 1 | H5: =G5*F5 -> 50000 | I5: √ | J5: 1 | K5: 1 | L5: 1.5 | M5: =IF(AND(K5*L5*30*N5>H5/J5,I5=""),"לרכוש","לא לרכוש") -> לא לרכוש | N5: 1000 | P5: 3 | Q5: =IF(I5=√, ) -> #NAME? | R5: =P5*L5*J5 -> 4.5 | S5: =IF(R5>$AA$8,IF(R5<$AA$9,$AB$9,$AB$10), $AB$8) -> 1 | T5: 1 | W5: 0.5 | X5: 23
A6: ='רשימת מכשור 2015'!A5 -> אנלייזר פחמן אורגני | B6: ='רשימת מכשור 2015'!B5 -> Mettler Toledo | C6: ='רשימת מכשור 2015'!C5 -> 5000TOC | D6: ='רשימת מכשור 2015'!D5 -> PW STORAGE 2500 | E6: ='רשימת מכשור 2015'!E5 -> 1-1-606-TOC-001 | F6: ='רשימת מכשור 2015'!F5 -> 50000 | G6: 1 | H6: =G6*F6 -> 50000 | I6: √ | J6: 1 | K6: 1 | L6: 1.5 | M6: =IF(AND(K6*L6*30*N6>H6/J6,I6=""),"לרכוש","לא לרכוש") -> לא לרכוש | N6: 1000 | P6: 3 | R6: =P6*L6*J6 -> 4.5 | S6: =IF(R6>$AA$8,IF(R6<$AA$9,$AB$9,$AB$10), $AB$8) -> 1 | T6: 1 | W6: 0.6 | X6: 1 | Z6: טבלת עזר
A7: ='רשימת מכשור 2015'!A7 -> multi chanel | B7: ='רשימת מכשור 2015'!B7 -> Mettler Toledo | C7: ='רשימת מכשור 2015'!C7 -> 770MAX | D7: ='רשימת מכשור 2015'!D7 -> 5000 | E7: ='רשימת מכשור 2015'!E7 -> N/A | F7: ='רשימת מכשור 2015'!F7 -> 10000 | G7: 1 | H7: 20000 | I7: √ | J7: 1 | K7: 1 | L7: 1.5 | M7: לא לרכוש | N7: 1000 | P7: 5 | R7: =P7*L7*J7 -> 7.5 | S7: =IF(R7>$AA$8,IF(R7<$AA$9,$AB$9,$AB$10), $AB$8) -> 1 | T7: 1 | W7: 0.8 | X7: 4 | Z7: מ | AA7: עד | AB7: מס יחידות למלאי
A8: ='רשימת מכשור 2015'!A9 -> אנלייזר קשיות | B8: ='רשימת מכשור 2015'!B9 -> ABB ISRAEL | C8: ='רשימת מכשור 2015'!C9 -> AW101/.1.2.1.1 | D8: ='רשימת מכשור 2015'!D9 -> HSW | E8: ='רשימת מכשור 2015'!E9 -> 1-1-57-HIC-1 | F8: ='רשימת מכשור 2015'!F9 -> 18000 | G8: 1 | H8: 18000 | J8: 1 | K8: 1 | N8: 1000 | P8: 1 | R8: =P8*L8*J8 -> 0 | S8: =IF(R8>$AA$8,IF(R8<$AA$9,$AB$9,$AB$10), $AB$8) -> 1 | T8: 1 | W8: 1 | X8: 26 | Z8: 0 | AA8: 8 | AB8: 1
A9: ='רשימת מכשור 2015'!A10 -> מד זרימה | B9: ='רשימת מכשור 2015'!B10 -> Liquid Controls Sponsler | C9: ='רשימת מכשור 2015'!C10 -> SP3/4-CS-PHL-3/4G-6MCIX3A | D9: ='רשימת מכשור 2015'!D10 -> CDI | E9: ='רשימת מכשור 2015'!E10 -> 1-1-134-FIC-1 | F9: ='רשימת מכשור 2015'!F10 -> 14000 | G9: 1 | H9: =G9*F9 -> 14000 | I9: √ | J9: 1 | K9: 1 | L9: 1.5 | M9: =IF(AND(K9*L9*30*N9>H9/J9,I9=""),"לרכוש","לא לרכוש") -> לא לרכוש | N9: 1000 | P9: 3 | R9: =P9*L9*J9 -> 4.5 | S9: =IF(R9>$AA$8,IF(R9<$AA$9,$AB$9,$AB$10), $AB$8) -> 1 | T9: 1 | W9: 1.2 | X9: 1 | Z9: 9 | AA9: 18 | AB9: 2
A10: ='רשימת מכשור 2015'!A12 -> משדר זרימה | B10: ='רשימת מכשור 2015'!B12 -> Liquid Controls Sponsler | C10: ='רשימת מכשור 2015'!C12 -> SP3/4-CS-PHL -3/4G-6MCIX3A | D10: ='רשימת מכשור 2015'!D12 -> PW PRODUCTION 2500 | E10: ='רשימת מכשור 2015'!E12 -> 1-1-604-FIT-001 | F10: ='רשימת מכשור 2015'!F12 -> 12000 | G10: 1 | H10: =G10*F10 -> 12000 | I10: √ | J10: 1 | K10: 0 | L10: 1.5 | M10: =IF(AND(K10*L10*30*N10>H10/J10,I10=""),"לרכוש","לא לרכוש") -> לא לרכוש | N10: 1000 | P10: 3 | R10: =P10*L10*J10 -> 4.5 | S10: =IF(R10>$AA$8,IF(R10<$AA$9,$AB$9,$AB$10), $AB$8) -> 1 | T10: 1 | W10: 1.4 | X10: 2 | Z10: 19 | AA10: 1000 | AB10: 3
A11: ='רשימת מכשור 2015'!A13 -> מד מפלס | B11: ='רשימת מכשור 2015'!B13 -> E+H | C11: ='רשימת מכשור 2015'!C13 -> MICROPILOT M FMR245-AETEJAA2AA | D11: ='רשימת מכשור 2015'!D13 -> NaOH | E11: ='רשימת מכשור 2015'!E13 -> 1-1-5-LC-1 | F11: ='רשימת מכשור 2015'!F13 -> 120000 | G11: 1 | H11: 12000 | J11: 1 | K11: 1 | L11: 1.5 | M11: =IF(AND(K11*L11*30*N11>H11/J11,I11=""),"לרכוש","לא לרכוש") -> לרכוש | N11: 1000 | P11: 2 | R11: =P11*L11*J11 -> 3 | S11: =IF(R11>$AA$8,IF(R11<$AA$9,$AB$9,$AB$10), $AB$8) -> 1 | T11: 1 | W11: 1.5 | X11: 20
A12: ='רשימת מכשור 2015'!A14 -> מד מפלס | B12: ='רשימת מכשור 2015'!B14 -> E+H | C12: ='רשימת מכשור 2015'!C14 -> MICROPILOT M FMR245-AETEJAA2AA | D12: ='רשימת מכשור 2015'!D14 -> ACID | E12: ='רשימת מכשור 2015'!E14 -> 1-1-141-LC-1 | F12: ='רשימת מכשור 2015'!F14 -> 120000 | G12: 1 | H12: 12000 | J12: 1 | K12: 1 | L12: 1.5 | M12: =IF(AND(K12*L12*30*N12>H12/J12,I12=""),"לרכוש","לא לרכוש") -> לרכוש | N12: 1000 | P12: 2 | R12: =P12*L12*J12 -> 3 | S12: =IF(R12>$AA$8,IF(R12<$AA$9,$AB$9,$AB$10), $AB$8) -> 1 | T12: 1 | W12: 1.8 | X12: 1
A13: ='רשימת מכשור 2015'!A15 -> מד מפלס | B13: ='רשימת מכשור 2015'!B15 -> E+H | C13: ='רשימת מכשור 2015'!C15 -> LEVELFLEX M FMP43-AS5TDJB21A2B | D13: ='רשימת מכשור 2015'!D15 -> WFI-PRODUCTION/STORAGE | E13: ='רשימת מכשור 2015'!E15 -> 25-LT-001 | F13: ='רשימת מכשור 2015'!F15 -> 12000 | G13: 1 | H13: =G13*F13 -> 12000 | J13: 1 | K13: 1 | L13: 1.5 | M13: =IF(AND(K13*L13*30*N13>H13/J13,I13=""),"לרכוש","לא לרכוש") -> לרכוש | N13: 1000 | P13: 1 | R13: =P13*L13*J13 -> 1.5 | S13: =IF(R13>$AA$8,IF(R13<$AA$9,$AB$9,$AB$10), $AB$8) -> 1 | T13: 1 | W13: 2 | X13: 15
A14: ='רשימת מכשור 2015'!A16 -> מד מפלס | B14: ='רשימת מכשור 2015'!B16 -> E+H | C14: ='רשימת מכשור 2015'!C16 -> LEVELFLEX M FMP41C-AATDKB21A2A | D14: ='רשימת מכשור 2015'!D16 -> SW SYSTEM | E14: ='רשימת מכשור 2015'!E16 -> 1-1-132-LIC-1 | F14: ='רשימת מכשור 2015'!F16 -> 12000 | G14: 1 | H14: =G14*F14 -> 12000 | J14: 1 | K14: 1 | L14: 1.5 | M14: =IF(AND(K14*L14*30*N14>H14/J14,I14=""),"לרכוש","לא לרכוש") -> לרכוש | N14: 1000 | P14: 1 | R14: =P14*L14*J14 -> 1.5 | S14: =IF(R14>$AA$8,IF(R14<$AA$9,$AB$9,$AB$10), $AB$8) -> 1 | T14: 1 | W14: 2.4 | X14: 2
A15: ='רשימת מכשור 2015'!A17 -> משדר לחץ | B15: ='רשימת מכשור 2015'!B17 -> LABOM | C15: ='רשימת מכשור 2015'!C17 -> LABOM - CV3110 | D15: ='רשימת מכשור 2015'!D17 -> צנטרפוגה | E15: ='רשימת מכשור 2015'!E17 -> PIAL 02-9-020 | F15: ='רשימת מכשור 2015'!F17 -> 10000 | G15: 1 | H15: =G15*F15 -> 10000 | J15: 1 | K15: 1 | L15: 1.5 | M15: =IF(AND(K15*L15*30*N15>H15/J15,I15=""),"לרכוש","לא לרכוש") -> לרכוש | N15: 1000 | P15: 3 | R15: =P15*L15*J15 -> 4.5 | S15: =IF(R15>$AA$8,IF(R15<$AA$9,$AB$9,$AB$10), $AB$8) -> 1 | T15: 1 | W15: 2.4 | X15: 2
A16: ='רשימת מכשור 2015'!A19 -> multi chanel | B16: ='רשימת מכשור 2015'!B19 -> THORNTON | C16: ='רשימת מכשור 2015'!C19 -> 770 max | D16: ='רשימת מכשור 2015'!D19 -> PW פיילוט | E16: ='רשימת מכשור 2015'!E19 -> 0 | F16: ='רשימת מכשור 2015'!F19 -> 10000 | G16: 1 | H16: =G16*F16 -> 10000 | I16: √ | J16: 1 | K16: 1 | L16: 1 | M16: =IF(AND(K16*L16*30*N16>H16/J16,I16=""),"לרכוש","לא לרכוש") -> לא לרכוש | N16: 1000 | P16: 5 | R16: =P16*L16*J16 -> 5 | S16: =IF(R16>$AA$8,IF(R16<$AA$9,$AB$9,$AB$10), $AB$8) -> 1 | T16: 1 | W16: 3 | X16: 21
A17: ='רשימת מכשור 2015'!A20 -> מד כלור | B17: ='רשימת מכשור 2015'!B20 -> E+H | C17: ='רשימת מכשור 2015'!C20 -> transmitter : liquisys m CCM253-EK8005 FLOWFIT-W CCA250 | D17: ='רשימת מכשור 2015'!D20 -> CLW | E17: ='רשימת מכשור 2015'!E20 -> 1-1-1-CLIC-1 | F17: ='רשימת מכשור 2015'!F20 -> 7000 | G17: 1 | H17: =G17*F17 -> 7000 | J17: 1 | K17: 1 | L17: 1.5 | M17: =IF(AND(K17*L17*30*N17>H17/J17,I17=""),"לרכוש","לא לרכוש") -> לרכוש | N17: 1000 | P17: 1 | R17: =P17*L17*J17 -> 1.5 | S17: =IF(R17>$AA$8,IF(R17<$AA$9,$AB$9,$AB$10), $AB$8) -> 1 | T17: 1 | W17: 3.6 | X17: 1
A18: ='רשימת מכשור 2015'!A21 -> מד מפלס | B18: ='רשימת מכשור 2015'!B21 -> E+H | C18: ='רשימת מכשור 2015'!C21 -> LIQUICAP M FMI52-A1BTDJA2A1A | D18: ='רשימת מכשור 2015'!D21 -> CLW | E18: ='רשימת מכשור 2015'!E21 -> 1-1-1-LC-1 | F18: ='רשימת מכשור 2015'!F21 -> 10000 | G18: 1 | H18: =G18*F18 -> 10000 | J18: 1 | K18: 1 | L18: 1.5 | M18: =IF(AND(K18*L18*30*N18>H18/J18,I18=""),"לרכוש","לא לרכוש") -> לרכוש | N18: 1000 | P18: 1 | R18: =P18*L18*J18 -> 1.5 | S18: =IF(R18>$AA$8,IF(R18<$AA$9,$AB$9,$AB$10), $AB$8) -> 1 | T18: 1 | W18: 4 | X18: 7
A19: ='רשימת מכשור 2015'!A23 -> multi chanel | B19: ='רשימת מכשור 2015'!B23 -> torenton | C19: ='רשימת מכשור 2015'!C23 -> torenton | D19: ='רשימת מכשור 2015'!D23 -> WFI-PRODUCTION/STORAGE | E19: ='רשימת מכשור 2015'!E23 -> 25-CIT-1 | F19: ='רשימת מכשור 2015'!F23 -> 10000 | G19: 1 | H19: =G19*F19 -> 10000 | I19: √ | J19: 1 | K19: 1 | L19: 1.2 | M19: =IF(AND(K19*L19*30*N19>H19/J19,I19=""),"לרכוש","לא לרכוש") -> לא לרכוש | N19: 1000 | P19: 5 | R19: =P19*L19*J19 -> 6 | S19: =IF(R19>$AA$8,IF(R19<$AA$9,$AB$9,$AB$10), $AB$8) -> 1 | T19: 1 | W19: 4.5 | X19: 7
A20: ='רשימת מכשור 2015'!A25 -> מד זרימה | B20: ='רשימת מכשור 2015'!B25 -> ABB ISRAEL | C20: ='רשימת מכשור 2015'!C25 -> ABB - FEH311 | D20: ='רשימת מכשור 2015'!D25 -> צנטרפוגה | E20: ='רשימת מכשור 2015'!E25 -> FIC 02-9-041 | F20: ='רשימת מכשור 2015'!F25 -> 9133 | G20: 1 | H20: =G20*F20 -> 9133 | J20: 1 | K20: 1 | L20: 1.5 | M20: =IF(AND(K20*L20*30*N20>H20/J20,I20=""),"לרכוש","לא לרכוש") -> לרכוש | N20: 1000 | P20: 2 | R20: =P20*L20*J20 -> 3 | S20: =IF(R20>$AA$8,IF(R20<$AA$9,$AB$9,$AB$10), $AB$8) -> 1 | T20: 1 | W20: 5 | X20: 6
A21: ='רשימת מכשור 2015'!A26 -> משדר חמצן | B21: ='רשימת מכשור 2015'!B26 -> Drager | C21: ='רשימת מכשור 2015'!C26 -> polytron 7000 | D21: ='רשימת מכשור 2015'!D26 -> GAS phase cell bank | E21: ='רשימת מכשור 2015'!E26 -> 1-2-2010-OM-2 | F21: ='רשימת מכשור 2015'!F26 -> 7500 | G21: 1 | H21: =G21*F21 -> 7500 | J21: 1 | K21: 1 | L21: 1 | M21: =IF(AND(K21*L21*30*N21>H21/J21,I21=""),"לרכוש","לא לרכוש") -> לרכוש | N21: 1000 | P21: 1 | R21: =P21*L21*J21 -> 1 | S21: =IF(R21>$AA$8,IF(R21<$AA$9,$AB$9,$AB$10), $AB$8) -> 1 | T21: 1 | W21: 5.5 | X21: 1
A22: ='רשימת מכשור 2015'!A27 -> מד כלור | B22: ='רשימת מכשור 2015'!B27 -> E+H | C22: ='רשימת מכשור 2015'!C27 -> Element : ccs140 transmitter : liquisys m cell : flowfit cca250 | D22: ='רשימת מכשור 2015'!D27 -> PRETREATMENT SYSTEM | E22: ='רשימת מכשור 2015'!E27 -> 1-1-131-CLIC-1 | F22: ='רשימת מכשור 2015'!F27 -> 7000 | G22: 1 | H22: =G22*F22 -> 7000 | J22: 1 | K22: 1 | L22: 1.5 | M22: =IF(AND(K22*L22*30*N22>H22/J22,I22=""),"לרכוש","לא לרכוש") -> לרכוש | N22: 1000 | P22: 2 | R22: =P22*L22*J22 -> 3 | S22: =IF(R22>$AA$8,IF(R22<$AA$9,$AB$9,$AB$10), $AB$8) -> 1 | T22: 1 | W22: 6 | X22: 3
A23: ='רשימת מכשור 2015'!A28 -> אלקטרודת מוליכות | B23: ='רשימת מכשור 2015'!B28 -> E+H | C23: ='רשימת מכשור 2015'!C28 -> Element : cls21-c1e4a Transmitter : liquisys m clm253-cd8005 | D23: ='רשימת מכשור 2015'!D28 -> PRETREATMENT SYSTEM | E23: ='רשימת מכשור 2015'!E28 -> 1-1-131-CIT 1 | F23: ='רשימת מכשור 2015'!F28 -> 7000 | G23: 1 | H23: =G23*F23 -> 7000 | J23: 1 | K23: 1 | L23: 1.5 | M23: =IF(AND(K23*L23*30*N23>H23/J23,I23=""),"לרכוש","לא לרכוש") -> לרכוש | N23: 1000 | P23: 2 | R23: =P23*L23*J23 -> 3 | S23: =IF(R23>$AA$8,IF(R23<$AA$9,$AB$9,$AB$10), $AB$8) -> 1 | T23: 1 | W23: 6.5 | X23: 1
A24: ='רשימת מכשור 2015'!A29 -> אלקטרודת מוליכות | B24: ='רשימת מכשור 2015'!B29 -> Mettler Toledo | C24: ='רשימת מכשור 2015'!C29 -> Inpro 7108 1.5"TC 5200800 M400 | D24: ='רשימת מכשור 2015'!D29 -> MEDIA | E24: ='רשימת מכשור 2015'!E29 -> 1-1-56-CIC-1 | F24: ='רשימת מכשור 2015'!F29 -> 4000 | G24: 1 | H24: =G24*F24 -> 4000 | I24: √ | J24: 1 | K24: 1 | L24: 1.5 | M24: =IF(AND(K24*L24*30*N24>H24/J24,I24=""),"לרכוש","לא לרכוש") -> לא לרכוש | N24: 1000 | P24: 1 | R24: =P24*L24*J24 -> 1.5 | S24: =IF(R24>$AA$8,IF(R24<$AA$9,$AB$9,$AB$10), $AB$8) -> 1 | T24: 1 | W24: 7 | X24: 1
A25: ='רשימת מכשור 2015'!A30 -> מד רדוקס | B25: ='רשימת מכשור 2015'!B30 -> EUTECH INSTRUMENT | C25: ='רשימת מכשור 2015'!C30 -> Sensor: Pt4805-DPA-SC-S8 Transmiter: ALPHA pH800 | D25: ='רשימת מכשור 2015'!D30 -> SW SYSTEM | E25: ='רשימת מכשור 2015'!E30 -> 1-1-132-ORP-1 | F25: ='רשימת מכשור 2015'!F30 -> 7000 | G25: 1 | H25: =G25*F25 -> 7000 | J25: 1 | K25: 1 | L25: 1.5 | M25: =IF(AND(K25*L25*30*N25>H25/J25,I25=""),"לרכוש","לא לרכוש") -> לרכוש | N25: 1000 | P25: 2 | R25: =P25*L25*J25 -> 3 | S25: =IF(R25>$AA$8,IF(R25<$AA$9,$AB$9,$AB$10), $AB$8) -> 1 | T25: 1 | W25: 7.5 | X25: 2
A26: ='רשימת מכשור 2015'!A32 -> מד רעידות | B26: ='רשימת מכשור 2015'!B32 -> GEAיצור עצמי | C26: ='רשימת מכשור 2015'!C32 -> HW - sensor messtechnik pch | D26: ='רשימת מכשור 2015'!D32 -> צנטרפוגה | E26: ='רשימת מכשור 2015'!E32 -> NAH/HH01-9-018 | F26: ='רשימת מכשור 2015'!F32 -> 6615 | G26: 1 | H26: =G26*F26 -> 6615 | J26: 1 | K26: 1 | L26: 1.5 | M26: =IF(AND(K26*L26*30*N26>H26/J26,I26=""),"לרכוש","לא לרכוש") -> לרכוש | N26: 1000 | P26: 1 | R26: =P26*L26*J26 -> 1.5 | S26: =IF(R26>$AA$8,IF(R26<$AA$9,$AB$9,$AB$10), $AB$8) -> 1 | T26: 1 | W26: 8.4 | X26: 1
A27: ='רשימת מכשור 2015'!A33 -> משדר לחץ | B27: ='רשימת מכשור 2015'!B33 -> E+H | C27: ='רשימת מכשור 2015'!C33 -> PMP46-RE13SBJPGD | D27: ='רשימת מכשור 2015'!D33 -> PW STORAGE 2500 | E27: ='רשימת מכשור 2015'!E33 -> 1-1-606-PIT-007 | F27: ='רשימת מכשור 2015'!F33 -> 6000 | G27: 1 | H27: =G27*F27 -> 6000 | I27: √ | J27: 1 | K27: 1 | L27: 1 | M27: =IF(AND(K27*L27*30*N27>H27/J27,I27=""),"לרכוש","לא לרכוש") -> לא לרכוש | N27: 1000 | P27: 1 | R27: =P27*L27*J27 -> 1 | S27: =IF(R27>$AA$8,IF(R27<$AA$9,$AB$9,$AB$10), $AB$8) -> 1 | T27: 1 | W27: 9 | X27: 3
A28: ='רשימת מכשור 2015'!A34 -> משדר לחץ | B28: ='רשימת מכשור 2015'!B34 -> Carabar M | C28: ='רשימת מכשור 2015'!C34 -> D800AB0112A | D28: ='רשימת מכשור 2015'!D34 -> WFI-PRODUCTION/STORAGE | E28: ='רשימת מכשור 2015'!E34 -> 25-PIC-1 | F28: ='רשימת מכשור 2015'!F34 -> 6000 | G28: 1 | H28: =G28*F28 -> 6000 | I28: √ | J28: 1 | K28: 1 | L28: 1.2 | M28: =IF(AND(K28*L28*30*N28>H28/J28,I28=""),"לרכוש","לא לרכוש") -> לא לרכוש | N28: 1000 | P28: 1 | R28: =P28*L28*J28 -> 1.2 | S28: =IF(R28>$AA$8,IF(R28<$AA$9,$AB$9,$AB$10), $AB$8) -> 1 | T28: 1 | W28: 9.1 | X28: 1
A29: ='רשימת מכשור 2015'!A35 -> משדר לחץ | B29: ='רשימת מכשור 2015'!B35 -> E+H | C29: ='רשימת מכשור 2015'!C35 -> CERABAR M PMC45 | D29: ='רשימת מכשור 2015'!D35 -> RO PRODUCTION | E29: ='רשימת מכשור 2015'!E35 -> 1-1-133-PIC-2 | F29: ='רשימת מכשור 2015'!F35 -> 6000 | G29: 1 | H29: =G29*F29 -> 6000 | I29: √ | J29: 1 | K29: 1 | L29: 1.5 | M29: =IF(AND(K29*L29*30*N29>H29/J29,I29=""),"לרכוש","לא לרכוש") -> לא לרכוש | N29: 1000 | P29: 1 | R29: =P29*L29*J29 -> 1.5 | S29: =IF(R29>$AA$8,IF(R29<$AA$9,$AB$9,$AB$10), $AB$8) -> 1 | T29: 1 | W29: 10.5 | X29: 1
A30: ='רשימת מכשור 2015'!A36 -> משדר לחץ | B30: ='רשימת מכשור 2015'!B36 -> E+H | C30: ='רשימת מכשור 2015'!C36 -> CB012C01024 | D30: ='רשימת מכשור 2015'!D36 -> RO PRODUCTION | E30: ='רשימת מכשור 2015'!E36 -> 1-1-133-PIC-6 | F30: ='רשימת מכשור 2015'!F36 -> 6000 | G30: 1 | H30: =G30*F30 -> 6000 | J30: 1 | K30: 1 | L30: 1.5 | M30: =IF(AND(K30*L30*30*N30>H30/J30,I30=""),"לרכוש","לא לרכוש") -> לרכוש | N30: 1000 | P30: 2 | R30: =P30*L30*J30 -> 3 | S30: =IF(R30>$AA$8,IF(R30<$AA$9,$AB$9,$AB$10), $AB$8) -> 1 | T30: 1 | W30: 11 | X30: 2
A31: ='רשימת מכשור 2015'!A38 -> משדר לחץ | B31: ='רשימת מכשור 2015'!B38 -> E+H | C31: ='רשימת מכשור 2015'!C38 -> CERABAR M PMP46-RE17P1JPDGD | D31: ='רשימת מכשור 2015'!D38 -> MEDIA | E31: ='רשימת מכשור 2015'!E38 -> 1-1-56-PC-1 | F31: ='רשימת מכשור 2015'!F38 -> 6000 | G31: 1 | H31: =G31*F31 -> 6000 | I31: √ | J31: 1 | K31: 1 | L31: 1.5 | M31: =IF(AND(K31*L31*30*N31>H31/J31,I31=""),"לרכוש","לא לרכוש") -> לא לרכוש | N31: 1000 | P31: 2 | R31: =P31*L31*J31 -> 3 | S31: =IF(R31>$AA$8,IF(R31<$AA$9,$AB$9,$AB$10), $AB$8) -> 1 | T31: 1 | W31: 13.5 | X31: 1
A32: ='רשימת מכשור 2015'!A40 -> משדר לחץ | B32: ='רשימת מכשור 2015'!B40 -> E+H | C32: ='רשימת מכשור 2015'!C40 -> CERABAR M PMP46-RE13SVJPDGD | D32: ='רשימת מכשור 2015'!D40 -> CRUDE | E32: ='רשימת מכשור 2015'!E40 -> 1-1-28-PC-2 | F32: ='רשימת מכשור 2015'!F40 -> 6000 | G32: 1 | H32: =G32*F32 -> 6000 | I32: √ | J32: 1 | K32: 1 | L32: 1.5 | M32: =IF(AND(K32*L32*30*N32>H32/J32,I32=""),"לרכוש","לא לרכוש") -> לא לרכוש | N32: 1000 | P32: 5 | R32: =P32*L32*J32 -> 7.5 | S32: =IF(R32>$AA$8,IF(R32<$AA$9,$AB$9,$AB$10), $AB$8) -> 1 | T32: 1 | W32: 15 | X32: 4
A33: ='רשימת מכשור 2015'!A45 -> מד מפלס | B33: ='רשימת מכשור 2015'!B45 -> E+H | C33: ='רשימת מכשור 2015'!C45 -> LIQUCAP M FMI52-A1ATJJA1A1A | D33: ='רשימת מכשור 2015'!D45 -> PW STORAGE 2500 | E33: ='רשימת מכשור 2015'!E45 -> 1-1-606-LT-002 | F33: ='רשימת מכשור 2015'!F45 -> 5111 | G33: 1 | H33: =G33*F33 -> 5111 | J33: 1 | K33: 1 | L33: 1.5 | M33: =IF(AND(K33*L33*30*N33>H33/J33,I33=""),"לרכוש","לא לרכוש") -> לרכוש | N33: 1000 | P33: 1 | R33: =P33*L33*J33 -> 1.5 | S33: =IF(R33>$AA$8,IF(R33<$AA$9,$AB$9,$AB$10), $AB$8) -> 1 | T33: 1 | W33: 60 | X33: 2
A34: ='רשימת מכשור 2015'!A46 -> סעפת 20 ברז (מפעיל)ים | B34: ='רשימת מכשור 2015'!B46 -> FESTO ISRAEL | C34: ='רשימת מכשור 2015'!C46 -> FESTO | D34: ='רשימת מכשור 2015'!D46 -> צנטרפוגה | E34: ='רשימת מכשור 2015'!E46 -> N/A | F34: ='רשימת מכשור 2015'!F46 -> 5000 | G34: 1 | H34: =G34*F34 -> 5000 | J34: 1 | K34: 1 | L34: 0.5 | M34: =IF(AND(K34*L34*30*N34>H34/J34,I34=""),"לרכוש","לא לרכוש") -> לרכוש | N34: 1000 | P34: 1 | R34: =P34*L34*J34 -> 0.5 | S34: =IF(R34>$AA$8,IF(R34<$AA$9,$AB$9,$AB$10), $AB$8) -> 1 | T34: 1 | W34: 70 | X34: 1
A35: ='רשימת מכשור 2015'!A47 -> משדר לחץ | B35: ='רשימת מכשור 2015'!B47 -> Baumer | C35: ='רשימת מכשור 2015'!C47 -> PBMH 25B72RA14481202000 | D35: ='רשימת מכשור 2015'!D47 -> DISTILLERY | E35: ='רשימת מכשור 2015'!E47 -> 1-1-40-PT-01 | F35: ='רשימת מכשור 2015'!F47 -> 5000 | G35: 1 | H35: =G35*F35 -> 5000 | I35: √ | J35: 1 | K35: 1 | L35: 1.2 | M35: =IF(AND(K35*L35*30*N35>H35/J35,I35=""),"לרכוש","לא לרכוש") -> לא לרכוש | N35: 1000 | P35: 3 | R35: =P35*L35*J35 -> 3.6 | S35: =IF(R35>$AA$8,IF(R35<$AA$9,$AB$9,$AB$10), $AB$8) -> 1 | T35: 1
A36: ='רשימת מכשור 2015'!A50 -> LOAD CELL | B36: ='רשימת מכשור 2015'!B50 -> TEDEA | C36: ='רשימת מכשור 2015'!C50 -> 3410 | D36: ='רשימת מכשור 2015'!D50 -> MEDIA | E36: ='רשימת מכשור 2015'!E50 -> 1-1-8-WC-1 | F36: ='רשימת מכשור 2015'!F50 -> 1500 | G36: 1 | H36: =G36*F36 -> 1500 | I36: √ | J36: 1 | K36: 1 | L36: 0.5 | M36: =IF(AND(K36*L36*30*N36>H36/J36,I36=""),"לרכוש","לא לרכוש") -> לא לרכוש | N36: 1000 | P36: 27 | R36: =P36*L36*J36 -> 13.5 | S36: =IF(R36>$AA$8,IF(R36<$AA$9,$AB$9,$AB$10), $AB$8) -> 2 | T36: 2 | U36: המשמעות של שתי יחידות היא שגם לאחר תקלה תישאר במלאי יחידה אחת לגיבוי, יש כרגע 3 יחידות, להשתמש באחת מהן בהזדמנות הראשונה (1500 ₪)
A37: ='רשימת מכשור 2015'!A51 -> LOAD CELL | B37: ='רשימת מכשור 2015'!B51 -> REVERE | C37: ='רשימת מכשור 2015'!C51 -> RLC | D37: ='רשימת מכשור 2015'!D51 -> CRUDE | E37: ='רשימת מכשור 2015'!E51 -> 1-1-28-WC-1 | F37: ='רשימת מכשור 2015'!F51 -> 1500 | G37: 1 | H37: =G37*F37 -> 1500 | J37: 1 | K37: 1 | L37: 0.5 | M37: =IF(AND(K37*L37*30*N37>H37/J37,I37=""),"לרכוש","לא לרכוש") -> לרכוש | N37: 1000 | P37: 21 | R37: =P37*L37*J37 -> 10.5 | S37: =IF(R37>$AA$8,IF(R37<$AA$9,$AB$9,$AB$10), $AB$8) -> 2 | T37: 2 | U37: המשמעות של שתי יחידות היא שגם לאחר תקלה תישאר במלאי יחידה אחת לגיבוי, יש כרגע 3 יחידות, להשתמש באחת מהן בהזדמנות הראשונה (1500 ₪)
A38: ='רשימת מכשור 2015'!A57 -> מד מהירות | B38: ='רשימת מכשור 2015'!B57 -> p+f | C38: ='רשימת מכשור 2015'!C57 -> KFD2-UFC-EX1.D | D38: ='רשימת מכשור 2015'!D57 -> HARVEST | E38: ='רשימת מכשור 2015'!E57 -> 1-1-27-SIC-1 | F38: ='רשימת מכשור 2015'!F57 -> 4500 | G38: 1 | H38: =G38*F38 -> 4500 | J38: 1 | K38: 1 | L38: 1.5 | M38: =IF(AND(K38*L38*30*N38>H38/J38,I38=""),"לרכוש","לא לרכוש") -> לרכוש | N38: 1000 | P38: 1 | R38: =P38*L38*J38 -> 1.5 | S38: =IF(R38>$AA$8,IF(R38<$AA$9,$AB$9,$AB$10), $AB$8) -> 1 | T38: 1
A39: ='רשימת מכשור 2015'!A66 -> LOAD CELL | B39: ='רשימת מכשור 2015'!B66 -> TEDEA | C39: ='רשימת מכשור 2015'!C66 -> 3510 | D39: ='רשימת מכשור 2015'!D66 -> COLUMN 4/5 | E39: ='רשימת מכשור 2015'!E66 -> 1-1-4-WC-1 | F39: ='רשימת מכשור 2015'!F66 -> 1500 | G39: 1 | H39: =G39*F39 -> 1500 | J39: 1 | K39: 1 | L39: 0.5 | M39: =IF(AND(K39*L39*30*N39>H39/J39,I39=""),"לרכוש","לא לרכוש") -> לרכוש | N39: 1000 | P39: 3 | R39: =P39*L39*J39 -> 1.5 | S39: =IF(R39>$AA$8,IF(R39<$AA$9,$AB$9,$AB$10), $AB$8) -> 1 | T39: 1
A40: ='רשימת מכשור 2015'!A67 -> LOAD CELL | B40: ='רשימת מכשור 2015'!B67 -> ZEMIC | C40: ='רשימת מכשור 2015'!C67 -> BM11-C3-50KG-3B-SC | D40: ='רשימת מכשור 2015'!D67 -> COLUMN 4/5 | E40: ='רשימת מכשור 2015'!E67 -> 1-1-4-WC-2 | F40: ='רשימת מכשור 2015'!F67 -> 1500 | G40: 1 | H40: =G40*F40 -> 1500 | J40: 1 | K40: 1 | L40: 0.5 | M40: =IF(AND(K40*L40*30*N40>H40/J40,I40=""),"לרכוש","לא לרכוש") -> לרכוש | N40: 1000 | P40: 3 | R40: =P40*L40*J40 -> 1.5 | S40: =IF(R40>$AA$8,IF(R40<$AA$9,$AB$9,$AB$10), $AB$8) -> 1 | T40: 1
A41: ='רשימת מכשור 2015'!A68 -> מפסק גובה | B41: ='רשימת מכשור 2015'!B68 -> E+H ISRAEL | C41: ='רשימת מכשור 2015'!C68 -> E+H - FTL50H | D41: ='רשימת מכשור 2015'!D68 -> צנטרפוגה | E41: ='רשימת מכשור 2015'!E68 -> LSH 01-9-016 | F41: ='רשימת מכשור 2015'!F68 -> 4226 | G41: 1 | H41: =G41*F41 -> 4226 | J41: 1 | K41: 1 | L41: 1.5 | M41: =IF(AND(K41*L41*30*N41>H41/J41,I41=""),"לרכוש","לא לרכוש") -> לרכוש | N41: 1000 | P41: 2 | R41: =P41*L41*J41 -> 3 | S41: =IF(R41>$AA$8,IF(R41<$AA$9,$AB$9,$AB$10), $AB$8) -> 1 | T41: 1
...

Sheet רשימת מכשור לרכישה 
C2: רשימת חלקי חילוף מכשור לרכישה
B3: תיאור הציוד | C3: יצרן | D3: דגם | E3: מחיר ב₪ | F3: כמות נדרשת למלאי | G3: כמות מאותו דגם | H3: זמן אספקה (בחודשים) | I3: ציון משוקלל (זמן אספקה * מופעים * מחיר) | J3: עדיפות ע"פ ציון משוקלל | K3: הערה
B4: מפעיל לברז בקרה | C4: Belimo | D4: NR C24A/SR | E4: 1500 | F4: 1 | G4: 15 | H4: 0.5 | I4: =H4*G4*1/E4*10000 -> 50 | J4: 1 | K4: [תשתיות כללי]
B5: משדר לחץ | C5: E+H | D5: CERABAR M PMP46-RE13SBJPDGD | E5: 6000 | F5: 1 | G5: 8 | H5: 1 | I5: =H5*G5*1/E5*10000 -> 13.333333 | K5: [ייצור]קרוד,קציר , קולונות 2/3, קולונות 4/5, [תשתיות -5000] 133-PIC-1,2,6 מדי הלחץ משמשים להגנה על משאבות, מפסיקים את פעולת המשאבה. המשמעות היא שבמקרה של כשל תופסק העבודה בכל אחת מהמערכות הנ"ל
B6: מפעיל לברז בקרה | C6: Belimo | D6: NVG-24-MFT | E6: 1000 | F6: 1 | G6: 4 | H6: 0.5 | I6: =H6*G6*1/E6*10000 -> 20 | J6: 1 | K6: [תשתיות כללי] הדגם הוחלף לSV24A-SR-TPC , להזמין בצירוף מכתב שאין שינוי פונקציונאלי מהדגם הקודם
B7: מתמר טמפרטורה | C7: Controtec. | D7: משדר+PT-100 | E7: 1500 | F7: 1 | G7: 4 | H7: 0.5 | I7: =H7*G7*1/E7*10000 -> 13.333333 | J7: 1 | K7: [QC+יצור+פיילוט]
B8: מפסק לחץ הפרשי | C8: Dwyer | D8: ADPS-01 | E8: 250 | F8: 1 | G8: 4 | H8: 2.5 | I8: =H8*G8*1/E8*10000 -> 400 | J8: 3 | K8: [תשתיות כללי]
B9: מפסק לחץ הפרשי | C9: Beck. | D9: 930.83 | E9: 200 | F9: 1 | G9: 4 | H9: 3.5 | I9: =H9*G9*1/E9*10000 -> 700 | J9: 3 | K9: [תשתיות כללי] | L9: https://www.downloads.siemens.com/download-center/Download.aspx?pos=download&fct=getasset&id1=10861
B10: משדר לחץ | C10: ELCON | D10: ELCON | E10: 3000 | F10: 1 | G10: 3 | H10: 1 | I10: =H10*G10*1/E10*10000 -> 10 | J10: 1 | K10: [יצור]
B11: מפעיל לברז בקרה | C11: siemens | D11: ACVITEX SKD60 | E11: 1600 | F11: 1 | G11: 3 | H11: 0.5 | I11: =H11*G11*1/E11*10000 -> 9.375 | J11: 1 | K11: [פיילוט]
B12: מד לחות משולב | C12: ACI | D12: DU/RH5-D | E12: 1000 | F12: 1 | G12: 3 | H12: 9.5 | I12: =H12*G12*1/E12*10000 -> 285 | J12: 2 | K12: [תשתיות כללי]
B13: LOAD CELL | C13: TEDEA | D13: 3510 | E13: 1500 | F13: 1 | G13: 3 | H13: 1 | I13: =H13*G13*1/E13*10000 -> 20 | J13: 1 | K13: [יצור]
B14: מד טמפרטורה | C14: ELCON | D14: PT-100 TH-39 | E14: 500 | F14: 1 | G14: 2 | H14: 0.5 | I14: =H14*G14*1/E14*10000 -> 20 | J14: 1 | K14: [תשתיות כללי]
B15: מד לחץ | C15: ELCON | D15: 30.800G | E15: 1200 | F15: 1 | G15: 2 | H15: 1 | I15: =H15*G15*1/E15*10000 -> 16.666667 | J15: 1 | K15: [יצור]
B16: מפעיל לברז בקרה | C16: BELIMO | D16: LF24 | E16: 800 | F16: 1 | G16: 2 | H16: 0.5 | I16: =H16*G16*1/E16*10000 -> 12.5 | J16: 1 | K16: [תשתיות כללי]
B17: מפסק זרימה | C17: New Flow | D17: MF200 0.75" | E17: 2000 | F17: 1 | G17: 2 | H17: 1 | I17: =H17*G17*1/E17*10000 -> 10 | J17: 1 | K17: [תשתיות -5000]
B18: מד זרימה | C18: E+H | D18: Flowphant T DTT35-A1C111DB2AAB | E18: 3000 | F18: 1 | G18: 2 | H18: 1.5 | I18: =H18*G18*1/E18*10000 -> 10 | J18: 1 | K18: [תשתיות -5000]
B19: אלקטרודת רדוקס | C19: METTLER TOLEDO | D19: Sensor: Pt4805-DPA-SC-S8 Transmiter: ALPHA pH800 | E19: 3500 | F19: 1 | G19: 2 | H19: 1.5 | I19: =H19*G19*1/E19*10000 -> 8.5714286 | J19: 1 | K19: [תשתיות -2500]
B20: משדר לחץ הפרשי | C20: MICATRONE | D20: MF-P 0-1000PA | E20: 1200 | F20: 1 | G20: 2 | H20: 0.5 | I20: =H20*G20*1/E20*10000 -> 8.3333333 | J20: 1 | K20: [מחסן]
B21: מפסק גובה | C21: E+H ISRAEL | D21: E+H - FTL50H | E21: 4226 | F21: 1 | G21: 2 | H21: 1.5 | I21: =H21*G21*1/E21*10000 -> 7.0989115 | J21: 1 | K21: צנטריפוגה
B22: מד לחות משולב | C22: Rotronic | D22: HygroFlex | E22: 1500 | F22: 1 | G22: 2 | H22: 0.5 | I22: =H22*G22*1/E22*10000 -> 6.6666667 | J22: 1 | K22: [תשתיות כללי]
B23: מפעיל לברז בקרה | C23: SIEMENS | D23: ACVITEX SQX62 | E23: 2000 | F23: 1 | G23: 2 | H23: 0.5 | I23: =H23*G23*1/E23*10000 -> 5 | J23: 2 | K23: [תשתיות כללי]
B24: מד לחות משולב | C24: COMET | D24: T0213 | E24: 1500 | F24: 1 | G24: 2 | H24: 1.5 | I24: =H24*G24*1/E24*10000 -> 20 | J24: 3 | K24: [תשתיות כללי]
B25: מפעיל לברז בקרה | C25: KAMA | D25: PF KFD2-UFC-1.D | E25: 2500 | F25: 1 | G25: 2 | H25: 7.5 | I25: =H25*G25*1/E25*10000 -> 60 | J25: 2 | K25: [יצור]
B26: מד לחות משולב | C26: Autonics | D26: RH+T | E26: 1200 | F26: 1 | G26: 2 | H26: 8.5 | I26: =H26*G26*1/E26*10000 -> 141.66667 | J26: 2 | K26: [תשתיות כללי]
B27: מד מפלס | C27: E+H | D27: LIQUCAP M FMI52-A1ATJJA1A1A | E27: 4850 | F27: 1 | G27: 2 | H27: 10.5 | I27: =H27*G27*1/E27*10000 -> 43.298969 | K27: [תשתיות כללי]
B28: מד זרימה | C28: ABB ISRAEL | D28: ABB - FEH311 | E28: 9133 | F28: 1 | G28: 2 | H28: 0.5 | I28: =H28*G28*1/E28*10000 -> 1.0949305 | J28: 2 | K28: [ייצור] עצירת צינטרפוגה. המשמעות היא שבמקרה של כשל תופסק העבודה בצנטריפוגה
B29: מד מפלס | C29: E+H | D29: MICROPILOT M FMR245-AETEJAA2AA | E29: 12000 | F29: 1 | G29: 2 | H29: 1 | I29: =H29*G29*1/E29*10000 -> 1.6666667 | J29: 2 | K29: [תשתיות -CIP] לא תתפשר עבודה עם ומול מיכלי NaOH 141 ו 5 (מיכל NaOH מרוכז -מיכל NaOH המכיל תמיסה מדוללת). המשמעות היא שלא ניתן יהיה להכין תמיסת NaOH לטובת CIP ביצור ולכן לא ניתן יהיה לבצע CIP
B30: מד מפלס | C30: E+H | D30: LIQUICAP M FMI52-A1BTDJA2A1A | E30: 6864 | F30: 1 | G30: 2 | H30: 1 | I30: =H30*G30*1/E28*10000 -> 2.1898609 | J30: 2 | K30: [תשתיות -CIP] CLW HSWלא תתאפשר עבודה עם ומול המיכלים 1-1-1-LC-1 1-1-57-LC-1. המשמעות היא שלא ניתן יהיה להכין HSW או תמיסת NaOH לטובת CIP ביצור ולכן לא ניתן יהיה לבצע CIP
B31: מפסק לחץ | C31: SMC | D31: ISE 30 | E31: 300 | F31: 1 | G31: 1 | H31: 0.5 | I31: =H31*G31*1/E31*10000 -> 16.666667 | J31: 1 | K31: [תשתיות כללי]דגם SMC ISE40-01-62L תחום:-0.100-1.000MPA
B32: מפסק לחץ | C32: FESTO ISRAEL | D32: FESTO - MODEL:c172 | E32: 600 | F32: 1 | G32: 1 | H32: 1 | I32: =H32*G32*1/E32*10000 -> 16.666667 | J32: 1 | K32: [תשתיות -5000]FESTO 529027 C172 (SDE5 D10-FP-Q6E-P-K
B33: משדר טמפרטורה | C33: SIEMENS | D33: QAE 2120-010 | E33: 600 | F33: 1 | G33: 1 | H33: 1 | I33: =H33*G33*1/E33*10000 -> 16.666667 | J33: 1 | K33: [תשתיות -אוויר דחוס] QAE2120.010 Including protection pocket with threaded nipple G ½ A 100 mm PN 10 LG-Ni 1000 IP42 (IP54) 2)
B34: סולונואיד (מאפשר לחץ אוויר בלוח) | C34: FESTO ISRAEL | D34: FESTO MODEL:MFH-5-1/4-5 | E34: 600 | F34: 1 | G34: 1 | H34: 1 | I34: =H34*G34*1/E34*10000 -> 16.666667 | J34: 1 | K34: [יצור]
B35: משדר טמפרטורה | C35: Controtec. | D35: משדר+PT-100 ס"מ ראש ת | E35: 500 | F35: 1 | G35: 1 | H35: 0.5 | I35: =H35*G35*1/E35*10000 -> 10 | J35: 1 | K35: [תשתיות -5000]
B36: מד טמפרטורה | C36: Controtec. | D36: PT-100 ס"מ 3 | E36: 500 | F36: 1 | G36: 1 | H36: 0.5 | I36: =H36*G36*1/E36*10000 -> 10 | J36: 1 | K36: [תשתיות+יצור+פילוט] מספר מופעים במפעל
B37: מד טמפרטורה | C37: Controtec. | D37: PT-100 ס"מ 4 | E37: 500 | F37: 1 | G37: 1 | H37: 0.5 | I37: =H37*G37*1/E37*10000 -> 10 | J37: 1 | K37: [תשתיות+יצור+פילוט] מספר מופעים במפעל
B38: מד טמפרטורה | C38: Controtec. | D38: PT-100 ס"מ 5 | E38: 500 | F38: 1 | G38: 1 | H38: 0.5 | I38: =H38*G38*1/E38*10000 -> 10 | J38: 1 | K38: [תשתיות+יצור+פילוט] מספר מופעים במפעל
B39: מד טמפרטורה | C39: Controtec. | D39: PT-100 ס"מ 6 | E39: 500 | F39: 1 | G39: 1 | H39: 0.5 | I39: =H39*G39*1/E39*10000 -> 10 | J39: 1 | K39: [תשתיות+יצור+פילוט] מספר מופעים במפעל
